Workbook

Sheet Perfil F-v PRESS BANCA
A2: 1 RM DIARIO Y CARGA DE TRABAJO | G2: EVOLUCIÓN 1RM
B4: CELDAS EN COLOR AZUL EDITABLES | G4: CELDAS EN COLOR AZUL EDITABLES
B5: ANALISIS LEVANTAMIENTO | G5: ="EVOLUCIÓN 1RM"&"-"&'Perfil F-v PRESS BANCA'!J40 -> EVOLUCIÓN 1RM-PRESS BANCA
B6: PRESS BANCA | G6: FECHA | H6: Levantamiento (kg) | I6: Velocidad (m/s) | J6: %1RM | K6: 1RM (kg)
B7: PESO (Kg) | C7: VELOCIDAD (m/s) | G7: 43924 | H7: 120 | I7: 0.2 | J7: =IF((I7=""),(""),((('Perfil F-v PRESS BANCA'!$O$55-I7)/-'Perfil F-v PRESS BANCA'!$O$56))) -> 98.390805 | K7: =IF((I7=""),(NA()),((H7*100)/J7)) -> 121.96262
B8: 120 | C8: 0.16 | G8: 43925 | H8: 100 | I8: 0.35 | J8: =IF((I8=""),(""),((('Perfil F-v PRESS BANCA'!$O$55-I8)/-'Perfil F-v PRESS BANCA'!$O$56))) -> 81.149425 | K8: =IF((I8=""),(NA()),((H8*100)/J8)) -> 123.22946
B9: % 1RM | C9: =(FIXED((('Perfil F-v PRESS BANCA'!O55-C8)/-'Perfil F-v PRESS BANCA'!O56),2)) -> 102,99
B10: R2 | C10: ='Perfil F-v PRESS BANCA'!O58 -> 0.99708481
B11: 1RM | C11: =(((B8*100)/C9)) -> 116.51617
B13: CÁLCULO PESO DE TRABAJO
B14: % 1RM de trabajo | C14: Peso a utilizar
B15: 95 | C15: =(C11*B15)/100 -> 110.69036
B17: PESO BARRA | C17: PESO MINIMO DISCO
B18: 20 | C18: 1.25
B19: PESO POR EXTREMO BARRA
B20: =(CEILING(((C15-B18)/2),C18)) -> 46.25
G35: =IF(('Perfil F-v PRESS BANCA'!C47=""),(""),(FIXED((('Perfil F-v PRESS BANCA'!$O$55-'Perfil F-v PRESS BANCA'!C47)/-'Perfil F-v PRESS BANCA'!$O$56),2)))
A36: GRÁFICAS | G36: PERFIL | M36: DATOS (no editable)
A37: PRESS BANCA
H38: CELDAS EN COLOR AZUL EDITABLES
H39: ="PERFIL"&" "& J40 -> PERFIL PRESS BANCA | N39: ='Perfil F-v PRESS BANCA'!J40 -> PRESS BANCA
I40: EJERCICIO | J40: PRESS BANCA | N40: CONSTANTE TEST PERFIL | P40: =FIXED(INTERCEPT('Perfil F-v PRESS BANCA'!J44:J48,'Perfil F-v PRESS BANCA'!I44:I48),4) -> 1,0560
H41: % 1RM conservador | I41: VELOCIDAD UMBRAL | J41: 0.19 | N41: PENDIENTE TEST PERFIL | P41: =FIXED(SLOPE('Perfil F-v PRESS BANCA'!J44:J48,'Perfil F-v PRESS BANCA'!I44:I48),4) -> -0,0078
H42: aconsejado para | I42: TEST | N42: ECUACIÓN TEST PERFIL | P42: =CONCATENATE("Y=",P41,"x + ",P40) -> Y=-0,0078x + 1,0560
H43: realizar el test | I43: PESO | J43: VELOCIDAD | N43: Se sustituye Y por V. Umbral: | P43: =CONCATENATE("X=((",P40,"-",'Perfil F-v PRESS BANCA'!$J$41,")/",-P41,")") -> X=((1,0560-0,19)/0,0078)
H44: 0.75 | I44: 80 | J44: 0.43 | N44: 1 RM (se despeja la x) | P44: =-(P40-'Perfil F-v PRESS BANCA'!J41)/P41 -> 111.02564
H45: 0.8 | I45: 85 | J45: 0.39 | N45: R2 TEST PERFIL | P45: =RSQ('Perfil F-v PRESS BANCA'!J44:J48,'Perfil F-v PRESS BANCA'!I44:I48) -> 0.99281984
H46: 0.85 | I46: 90 | J46: 0.36
H47: 0.9 | I47: 95 | J47: 0.32 | N47: RELACION VELOCIDAD - %1RM
H48: 0.95 | I48: 100 | J48: 0.27 | N48: PESO (kg) | O48: %1RM (X) | P48: VELOCIDAD (Y)
H49: Descanso: 3' | I49: R2 | J49: ='Perfil F-v PRESS BANCA'!P45 -> 0.99281984 | N49: ='Perfil F-v PRESS BANCA'!I44 -> 80 | O49: =(100*N49)/'Perfil F-v PRESS BANCA'!$P$44 -> 72.055427 | P49: ='Perfil F-v PRESS BANCA'!J44 -> 0.43
N50: ='Perfil F-v PRESS BANCA'!I45 -> 85 | O50: =(100*N50)/'Perfil F-v PRESS BANCA'!$P$44 -> 76.558891 | P50: ='Perfil F-v PRESS BANCA'!J45 -> 0.39
H51: Levantar con velocidad intencional máxima y técnica idéntica | N51: ='Perfil F-v PRESS BANCA'!I46 -> 90 | O51: =(100*N51)/'Perfil F-v PRESS BANCA'!$P$44 -> 81.062356 | P51: ='Perfil F-v PRESS BANCA'!J46 -> 0.36
H52: R2 superiores 0,99 ofrecen mediciones de 1RM muy precisas | N52: ='Perfil F-v PRESS BANCA'!I47 -> 95 | O52: =(100*N52)/'Perfil F-v PRESS BANCA'!$P$44 -> 85.56582 | P52: ='Perfil F-v PRESS BANCA'!J47 -> 0.32
H53: R2 entre 0,99-0,98 pueden sesgar el 1RM hasta un 5% | N53: ='Perfil F-v PRESS BANCA'!I48 -> 100 | O53: =(100*N53)/'Perfil F-v PRESS BANCA'!$P$44 -> 90.069284 | P53: ='Perfil F-v PRESS BANCA'!J48 -> 0.27
H54: R2 inferior a 0,98 aconsejan repetir el test | N54: ='Perfil F-v PRESS BANCA'!P44 -> 111.02564 | O54: =(100*N54)/'Perfil F-v PRESS BANCA'!$P$44 -> 100 | P54: ='Perfil F-v PRESS BANCA'!J41 -> 0.19
N55: CONSTANTE FINAL | O55: =FIXED(INTERCEPT(P49:P54,O49:O54),4) -> 1,0560
N56: PENDIENTE FINAL | O56: =FIXED(SLOPE(P49:P54,O49:O54),4) -> -0,0087
N57: ECUACIÓN FINAL | O57: =CONCATENATE("Y=",O56,"x + ",O55) -> Y=-0,0087x + 1,0560
N58: R2 FINAL | O58: =RSQ(P49:P54,O49:O54) -> 0.99708481
...

Sheet Perfil F-v SENTADILLA
A1: App MyLift® for iOS edición EXCEL. SENTADILLA
A3: 1 RM DIARIO Y CARGA DE TRABAJO | H3: EVOLUCIÓN 1RM
N4: Editado y desarrollado por:
B5: CELDAS EN COLOR AZUL EDITABLES | H5: CELDAS EN COLOR AZUL EDITABLES
B6: ANALISIS LEVANTAMIENTO | H6: ="EVOLUCIÓN 1RM"&"-"&'Perfil F-v SENTADILLA'!K41 -> EVOLUCIÓN 1RM-SENTADILLA | N6: Dr. Carlos Balsalobre Fernández
B7: ='Perfil F-v SENTADILLA'!K41 -> SENTADILLA | H7: FECHA | I7: Levantamiento (kg) | J7: Velocidad (m/s) | K7: %1RM | L7: 1RM (kg) | N7: David Marchante Domingo
B8: PESO (Kg) | C8: VELOCIDAD (m/s) | H8: 43924 | I8: 85 | J8: 0.69 | K8: =IF((J8=""),(""),((('Perfil F-v SENTADILLA'!$P$56-J8)/-'Perfil F-v SENTADILLA'!$P$57))) -> 64.07767 | L8: =IF((J8=""),(NA()),((I8*100)/K8)) -> 132.65152 | N8: Carlos Bustillo García
B9: 85 | C9: 0.69 | H9: 43925 | I9: 85 | J9: 0.74 | K9: =IF((J9=""),(""),((('Perfil F-v SENTADILLA'!$P$56-J9)/-'Perfil F-v SENTADILLA'!$P$57))) -> 59.223301 | L9: =IF((J9=""),(NA()),((I9*100)/K9)) -> 143.52459 | N9: Pedro Juan Spain
B10: % 1RM | C10: =(FIXED((('Perfil F-v SENTADILLA'!P56-C9)/-'Perfil F-v SENTADILLA'!P57),2)) -> 64,08 | K10: =IF((J10=""),(""),((('Perfil F-v SENTADILLA'!$P$56-J10)/-'Perfil F-v SENTADILLA'!$P$57))) | L10: =IF((J10=""),(NA()),((I10*100)/K10)) -> #N/A | N10: Mario Muñoz López
B11: R2 | C11: ='Perfil F-v SENTADILLA'!P59 -> 1 | K11: =IF((J11=""),(""),((('Perfil F-v SENTADILLA'!$P$56-J11)/-'Perfil F-v SENTADILLA'!$P$57))) | L11: =IF((J11=""),(NA()),((I11*100)/K11)) -> #N/A
B12: 1RM | C12: =(((B9*100)/C10)) -> 132.64669 | K12: =IF((J12=""),(""),((('Perfil F-v SENTADILLA'!$P$56-J12)/-'Perfil F-v SENTADILLA'!$P$57))) | L12: =IF((J12=""),(NA()),((I12*100)/K12)) -> #N/A
K13: =IF((J13=""),(""),((('Perfil F-v SENTADILLA'!$P$56-J13)/-'Perfil F-v SENTADILLA'!$P$57))) | L13: =IF((J13=""),(NA()),((I13*100)/K13)) -> #N/A
B14: CÁLCULO PESO DE TRABAJO | K14: =IF((J14=""),(""),((('Perfil F-v SENTADILLA'!$P$56-J14)/-'Perfil F-v SENTADILLA'!$P$57))) | L14: =IF((J14=""),(NA()),((I14*100)/K14)) -> #N/A
B15: % 1RM de trabajo | C15: Peso a utilizar | K15: =IF((J15=""),(""),((('Perfil F-v SENTADILLA'!$P$56-J15)/-'Perfil F-v SENTADILLA'!$P$57))) | L15: =IF((J15=""),(NA()),((I15*100)/K15)) -> #N/A
B16: 65 | C16: =(C12*B16)/100 -> 86.22035 | K16: =IF((J16=""),(""),((('Perfil F-v SENTADILLA'!$P$56-J16)/-'Perfil F-v SENTADILLA'!$P$57))) | L16: =IF((J16=""),(NA()),((I16*100)/K16)) -> #N/A
K17: =IF((J17=""),(""),((('Perfil F-v SENTADILLA'!$P$56-J17)/-'Perfil F-v SENTADILLA'!$P$57))) | L17: =IF((J17=""),(NA()),((I17*100)/K17)) -> #N/A
B18: PESO BARRA | C18: PESO MINIMO DISCO | K18: =IF((J18=""),(""),((('Perfil F-v SENTADILLA'!$P$56-J18)/-'Perfil F-v SENTADILLA'!$P$57))) | L18: =IF((J18=""),(NA()),((I18*100)/K18)) -> #N/A
B19: 20 | C19: 1.25 | K19: =IF((J19=""),(""),((('Perfil F-v SENTADILLA'!$P$56-J19)/-'Perfil F-v SENTADILLA'!$P$57))) | L19: =IF((J19=""),(NA()),((I19*100)/K19)) -> #N/A
B20: PESO POR EXTREMO BARRA | K20: =IF((J20=""),(""),((('Perfil F-v SENTADILLA'!$P$56-J20)/-'Perfil F-v SENTADILLA'!$P$57))) | L20: =IF((J20=""),(NA()),((I20*100)/K20)) -> #N/A | Q20: App Mylift for iOS
B21: =(CEILING(((C16-B19)/2),C19)) -> 33.75 | K21: =IF((J21=""),(""),((('Perfil F-v SENTADILLA'!$P$56-J21)/-'Perfil F-v SENTADILLA'!$P$57))) | L21: =IF((J21=""),(NA()),((I21*100)/K21)) -> #N/A
B22: ='Perfil F-v PRESS BANCA'!B21 | C22: ='Perfil F-v PRESS BANCA'!C21 | K22: =IF((J22=""),(""),((('Perfil F-v SENTADILLA'!$P$56-J22)/-'Perfil F-v SENTADILLA'!$P$57))) | L22: =IF((J22=""),(NA()),((I22*100)/K22)) -> #N/A
K23: =IF((J23=""),(""),((('Perfil F-v SENTADILLA'!$P$56-J23)/-'Perfil F-v SENTADILLA'!$P$57))) | L23: =IF((J23=""),(NA()),((I23*100)/K23)) -> #N/A
K24: =IF((J24=""),(""),((('Perfil F-v SENTADILLA'!$P$56-J24)/-'Perfil F-v SENTADILLA'!$P$57))) | L24: =IF((J24=""),(NA()),((I24*100)/K24)) -> #N/A
K25: =IF((J25=""),(""),((('Perfil F-v SENTADILLA'!$P$56-J25)/-'Perfil F-v SENTADILLA'!$P$57))) | L25: =IF((J25=""),(NA()),((I25*100)/K25)) -> #N/A
K26: =IF((J26=""),(""),((('Perfil F-v SENTADILLA'!$P$56-J26)/-'Perfil F-v SENTADILLA'!$P$57))) | L26: =IF((J26=""),(NA()),((I26*100)/K26)) -> #N/A
K27: =IF((J27=""),(""),((('Perfil F-v SENTADILLA'!$P$56-J27)/-'Perfil F-v SENTADILLA'!$P$57))) | L27: =IF((J27=""),(NA()),((I27*100)/K27)) -> #N/A
K28: =IF((J28=""),(""),((('Perfil F-v SENTADILLA'!$P$56-J28)/-'Perfil F-v SENTADILLA'!$P$57))) | L28: =IF((J28=""),(NA()),((I28*100)/K28)) -> #N/A
K29: =IF((J29=""),(""),((('Perfil F-v SENTADILLA'!$P$56-J29)/-'Perfil F-v SENTADILLA'!$P$57))) | L29: =IF((J29=""),(NA()),((I29*100)/K29)) -> #N/A
K30: =IF((J30=""),(""),((('Perfil F-v SENTADILLA'!$P$56-J30)/-'Perfil F-v SENTADILLA'!$P$57))) | L30: =IF((J30=""),(NA()),((I30*100)/K30)) -> #N/A
K31: =IF((J31=""),(""),((('Perfil F-v SENTADILLA'!$P$56-J31)/-'Perfil F-v SENTADILLA'!$P$57))) | L31: =IF((J31=""),(NA()),((I31*100)/K31)) -> #N/A
K32: =IF((J32=""),(""),((('Perfil F-v SENTADILLA'!$P$56-J32)/-'Perfil F-v SENTADILLA'!$P$57))) | L32: =IF((J32=""),(NA()),((I32*100)/K32)) -> #N/A
K33: =IF((J33=""),(""),((('Perfil F-v SENTADILLA'!$P$56-J33)/-'Perfil F-v SENTADILLA'!$P$57))) | L33: =IF((J33=""),(NA()),((I33*100)/K33)) -> #N/A
A37: GRÁFICAS | H37: PERFIL | N37: DATOS (no editable)
A38: ='Perfil F-v SENTADILLA'!K41 -> SENTADILLA
I39: CELDAS EN COLOR AZUL EDITABLES
I40: ="PERFIL"&" "& K41 -> PERFIL SENTADILLA | O40: ='Perfil F-v SENTADILLA'!K41 -> SENTADILLA
J41: EJERCICIO | K41: SENTADILLA | O41: CONSTANTE TEST PERFIL | Q41: =FIXED(INTERCEPT('Perfil F-v SENTADILLA'!K45:K49,'Perfil F-v SENTADILLA'!J45:J49),4) -> 1,3500
I42: % 1RM conservador | J42: VELOCIDAD UMBRAL | K42: 0.32 | O42: PENDIENTE TEST PERFIL | Q42: =FIXED(SLOPE('Perfil F-v SENTADILLA'!K45:K49,'Perfil F-v SENTADILLA'!J45:J49),4) -> -0,0100
I43: aconsejado para | J43: TEST | O43: ECUACIÓN TEST PERFIL | Q43: =CONCATENATE("Y=",Q42,"x + ",Q41) -> Y=-0,0100x + 1,3500
I44: realizar el test | J44: PESO | K44: VELOCIDAD | O44: Se sustituye Y por V. Umbral: | Q44: =CONCATENATE("X=((",Q41,"-",'Perfil F-v SENTADILLA'!$K$42,")/",-Q42,")") -> X=((1,3500-0,32)/0,01)
...

Sheet Perfil F-v PESO MUERTO
A1: App MyLift® for iOS edición EXCEL. PESO MUERTO
A3: 1 RM DIARIO Y CARGA DE TRABAJO | H3: EVOLUCIÓN 1RM
N4: Editado y desarrollado por:
B5: CELDAS EN COLOR AZUL EDITABLES | H5: CELDAS EN COLOR AZUL EDITABLES
B6: ANALISIS LEVANTAMIENTO | H6: ="EVOLUCIÓN 1RM"&"-"&'Perfil F-v PESO MUERTO'!K41 -> EVOLUCIÓN 1RM-PESO MUERTO | N6: Dr. Carlos Balsalobre Fernández
B7: ='Perfil F-v PESO MUERTO'!K41 -> PESO MUERTO | H7: FECHA | I7: Levantamiento (kg) | J7: Velocidad (m/s) | K7: %1RM | L7: 1RM (kg) | N7: David Marchante Domingo
B8: PESO (Kg) | C8: VELOCIDAD (m/s) | H8: 43924 | I8: 80 | J8: 0.6 | K8: =IF((J8=""),(""),((('Perfil F-v PESO MUERTO'!$P$56-J8)/-'Perfil F-v PESO MUERTO'!$P$57))) -> 83.191489 | L8: =IF((J8=""),(NA()),((I8*100)/K8)) -> 96.163683 | N8: Carlos Bustillo García
B9: 80 | C9: 0.6 | H9: 43925 | I9: 80 | J9: 0.69 | K9: =IF((J9=""),(""),((('Perfil F-v PESO MUERTO'!$P$56-J9)/-'Perfil F-v PESO MUERTO'!$P$57))) -> 76.808511 | L9: =IF((J9=""),(NA()),((I9*100)/K9)) -> 104.15512 | N9: Pedro Juan Spain
B10: % 1RM | C10: =(FIXED((('Perfil F-v PESO MUERTO'!P56-C9)/-'Perfil F-v PESO MUERTO'!P57),2)) -> 83,19 | K10: =IF((J10=""),(""),((('Perfil F-v PESO MUERTO'!$P$56-J10)/-'Perfil F-v PESO MUERTO'!$P$57))) | L10: =IF((J10=""),(NA()),((I10*100)/K10)) -> #N/A | N10: Mario Muñoz López
B11: R2 | C11: ='Perfil F-v PESO MUERTO'!P59 -> 0.99756826 | K11: =IF((J11=""),(""),((('Perfil F-v PESO MUERTO'!$P$56-J11)/-'Perfil F-v PESO MUERTO'!$P$57))) | L11: =IF((J11=""),(NA()),((I11*100)/K11)) -> #N/A
B12: 1RM | C12: =(((B9*100)/C10)) -> 96.165404 | K12: =IF((J12=""),(""),((('Perfil F-v PESO MUERTO'!$P$56-J12)/-'Perfil F-v PESO MUERTO'!$P$57))) | L12: =IF((J12=""),(NA()),((I12*100)/K12)) -> #N/A
K13: =IF((J13=""),(""),((('Perfil F-v PESO MUERTO'!$P$56-J13)/-'Perfil F-v PESO MUERTO'!$P$57))) | L13: =IF((J13=""),(NA()),((I13*100)/K13)) -> #N/A
B14: CÁLCULO PESO DE TRABAJO | K14: =IF((J14=""),(""),((('Perfil F-v PESO MUERTO'!$P$56-J14)/-'Perfil F-v PESO MUERTO'!$P$57))) | L14: =IF((J14=""),(NA()),((I14*100)/K14)) -> #N/A
B15: % 1RM de trabajo | C15: Peso a utilizar | K15: =IF((J15=""),(""),((('Perfil F-v PESO MUERTO'!$P$56-J15)/-'Perfil F-v PESO MUERTO'!$P$57))) | L15: =IF((J15=""),(NA()),((I15*100)/K15)) -> #N/A
B16: 65 | C16: =(C12*B16)/100 -> 62.507513 | K16: =IF((J16=""),(""),((('Perfil F-v PESO MUERTO'!$P$56-J16)/-'Perfil F-v PESO MUERTO'!$P$57))) | L16: =IF((J16=""),(NA()),((I16*100)/K16)) -> #N/A
K17: =IF((J17=""),(""),((('Perfil F-v PESO MUERTO'!$P$56-J17)/-'Perfil F-v PESO MUERTO'!$P$57))) | L17: =IF((J17=""),(NA()),((I17*100)/K17)) -> #N/A
B18: PESO BARRA | C18: PESO MINIMO DISCO | K18: =IF((J18=""),(""),((('Perfil F-v PESO MUERTO'!$P$56-J18)/-'Perfil F-v PESO MUERTO'!$P$57))) | L18: =IF((J18=""),(NA()),((I18*100)/K18)) -> #N/A
B19: 20 | C19: 1.25 | K19: =IF((J19=""),(""),((('Perfil F-v PESO MUERTO'!$P$56-J19)/-'Perfil F-v PESO MUERTO'!$P$57))) | L19: =IF((J19=""),(NA()),((I19*100)/K19)) -> #N/A
B20: PESO POR EXTREMO BARRA | K20: =IF((J20=""),(""),((('Perfil F-v PESO MUERTO'!$P$56-J20)/-'Perfil F-v PESO MUERTO'!$P$57))) | L20: =IF((J20=""),(NA()),((I20*100)/K20)) -> #N/A | Q20: App Mylift for iOS
B21: =(CEILING(((C16-B19)/2),C19)) -> 22.5 | K21: =IF((J21=""),(""),((('Perfil F-v PESO MUERTO'!$P$56-J21)/-'Perfil F-v PESO MUERTO'!$P$57))) | L21: =IF((J21=""),(NA()),((I21*100)/K21)) -> #N/A
B22: ='Perfil F-v PRESS BANCA'!B21 | C22: ='Perfil F-v PRESS BANCA'!C21 | K22: =IF((J22=""),(""),((('Perfil F-v PESO MUERTO'!$P$56-J22)/-'Perfil F-v PESO MUERTO'!$P$57))) | L22: =IF((J22=""),(NA()),((I22*100)/K22)) -> #N/A
K23: =IF((J23=""),(""),((('Perfil F-v PESO MUERTO'!$P$56-J23)/-'Perfil F-v PESO MUERTO'!$P$57))) | L23: =IF((J23=""),(NA()),((I23*100)/K23)) -> #N/A
K24: =IF((J24=""),(""),((('Perfil F-v PESO MUERTO'!$P$56-J24)/-'Perfil F-v PESO MUERTO'!$P$57))) | L24: =IF((J24=""),(NA()),((I24*100)/K24)) -> #N/A
K25: =IF((J25=""),(""),((('Perfil F-v PESO MUERTO'!$P$56-J25)/-'Perfil F-v PESO MUERTO'!$P$57))) | L25: =IF((J25=""),(NA()),((I25*100)/K25)) -> #N/A
K26: =IF((J26=""),(""),((('Perfil F-v PESO MUERTO'!$P$56-J26)/-'Perfil F-v PESO MUERTO'!$P$57))) | L26: =IF((J26=""),(NA()),((I26*100)/K26)) -> #N/A
K27: =IF((J27=""),(""),((('Perfil F-v PESO MUERTO'!$P$56-J27)/-'Perfil F-v PESO MUERTO'!$P$57))) | L27: =IF((J27=""),(NA()),((I27*100)/K27)) -> #N/A
K28: =IF((J28=""),(""),((('Perfil F-v PESO MUERTO'!$P$56-J28)/-'Perfil F-v PESO MUERTO'!$P$57))) | L28: =IF((J28=""),(NA()),((I28*100)/K28)) -> #N/A
K29: =IF((J29=""),(""),((('Perfil F-v PESO MUERTO'!$P$56-J29)/-'Perfil F-v PESO MUERTO'!$P$57))) | L29: =IF((J29=""),(NA()),((I29*100)/K29)) -> #N/A
K30: =IF((J30=""),(""),((('Perfil F-v PESO MUERTO'!$P$56-J30)/-'Perfil F-v PESO MUERTO'!$P$57))) | L30: =IF((J30=""),(NA()),((I30*100)/K30)) -> #N/A
K31: =IF((J31=""),(""),((('Perfil F-v PESO MUERTO'!$P$56-J31)/-'Perfil F-v PESO MUERTO'!$P$57))) | L31: =IF((J31=""),(NA()),((I31*100)/K31)) -> #N/A
K32: =IF((J32=""),(""),((('Perfil F-v PESO MUERTO'!$P$56-J32)/-'Perfil F-v PESO MUERTO'!$P$57))) | L32: =IF((J32=""),(NA()),((I32*100)/K32)) -> #N/A
K33: =IF((J33=""),(""),((('Perfil F-v PESO MUERTO'!$P$56-J33)/-'Perfil F-v PESO MUERTO'!$P$57))) | L33: =IF((J33=""),(NA()),((I33*100)/K33)) -> #N/A
A37: GRÁFICAS | H37: PERFIL | N37: DATOS (no editable)
A38: ='Perfil F-v PESO MUERTO'!K41 -> PESO MUERTO
I39: CELDAS EN COLOR AZUL EDITABLES
I40: ="PERFIL"&" "& K41 -> PERFIL PESO MUERTO | O40: ='Perfil F-v PESO MUERTO'!K41 -> PESO MUERTO
J41: EJERCICIO | K41: PESO MUERTO | O41: CONSTANTE TEST PERFIL | Q41: =FIXED(INTERCEPT('Perfil F-v PESO MUERTO'!K45:K49,'Perfil F-v PESO MUERTO'!J45:J49),4) -> 1,7730
I42: % 1RM conservador | J42: VELOCIDAD UMBRAL | K42: 0.36 | O42: PENDIENTE TEST PERFIL | Q42: =FIXED(SLOPE('Perfil F-v PESO MUERTO'!K45:K49,'Perfil F-v PESO MUERTO'!J45:J49),4) -> -0,0146
I43: aconsejado para | J43: TEST | O43: ECUACIÓN TEST PERFIL | Q43: =CONCATENATE("Y=",Q42,"x + ",Q41) -> Y=-0,0146x + 1,7730
I44: realizar el test | J44: PESO | K44: VELOCIDAD | O44: Se sustituye Y por V. Umbral: | Q44: =CONCATENATE("X=((",Q41,"-",'Perfil F-v PESO MUERTO'!$K$42,")/",-Q42,")") -> X=((1,7730-0,36)/0,0146)
...

Sheet Perfil F-v DOMINADAS
A1: ELABORA TU PERFIL DE FUERZA / VELOCIDAD (PRESS DE BANCA)
A3: 1 RM DIARIO Y CARGA DE TRABAJO | I3: EVOLUCIÓN 1RM
B5: CELDAS EN COLOR ROJO EDITABLES | I5: CELDAS EN COLOR ROJO
B6: ANALISIS LEVANTAMIENTO | I6: ="EVOLUCIÓN 1RM"&"-"&'Perfil F-v DOMINADAS'!M42 -> EVOLUCIÓN 1RM-PRESS DE BANCA
B7: ='Perfil F-v DOMINADAS'!M42 -> PRESS DE BANCA | I7: FECHA | J7: Peso corporal (kg) | K7: RPE Sesión | L7: Levantamiento total (kg) | M7: Velocidad (m/s) | N7: %1RM | O7: 1RM (kg)
B8: PESO (kg) | D8: VELOCIDAD (m/s) | I8: 43923 | J8: 85 | K8: 9 | L8: 100 | M8: 0.32 | N8: =IF((M8=""),(""),((('Perfil F-v DOMINADAS'!$S$56-M8)/-'Perfil F-v DOMINADAS'!$S$57))) -> 82.051282 | O8: =IF((M8=""),(NA()),((L8*100)/N8)) -> 121.875
B9: 120 | D9: 0.2 | I9: 43924 | J9: 84.3 | K9: 8 | L9: 100 | M9: 0.36 | N9: =IF((M9=""),(""),((('Perfil F-v DOMINADAS'!$S$56-M9)/-'Perfil F-v DOMINADAS'!$S$57))) -> 76.923077 | O9: =IF((M9=""),(NA()),((L9*100)/N9)) -> 130
B10: % 1RM | D10: =(FIXED((('Perfil F-v DOMINADAS'!S56-D9)/-'Perfil F-v DOMINADAS'!S57),2)) -> 97,44 | L10: =IF(AND(J10<>"",K10<>""),J10+K10,"") | N10: =IF((M10=""),(""),((('Perfil F-v DOMINADAS'!$S$56-M10)/-'Perfil F-v DOMINADAS'!$S$57))) | O10: =IF((M10=""),(NA()),((L10*100)/N10)) -> #N/A
B11: R2 | D11: ='Perfil F-v DOMINADAS'!S59 -> 1 | L11: =IF(AND(J11<>"",K11<>""),J11+K11,"") | N11: =IF((M11=""),(""),((('Perfil F-v DOMINADAS'!$S$56-M11)/-'Perfil F-v DOMINADAS'!$S$57))) | O11: =IF((M11=""),(NA()),((L11*100)/N11)) -> #N/A
B12: 1RM | D12: =((((B9)*100)/D10)) -> 123.15271 | L12: =IF(AND(J12<>"",K12<>""),J12+K12,"") | N12: =IF((M12=""),(""),((('Perfil F-v DOMINADAS'!$S$56-M12)/-'Perfil F-v DOMINADAS'!$S$57))) | O12: =IF((M12=""),(NA()),((L12*100)/N12)) -> #N/A
L13: =IF(AND(J13<>"",K13<>""),J13+K13,"") | N13: =IF((M13=""),(""),((('Perfil F-v DOMINADAS'!$S$56-M13)/-'Perfil F-v DOMINADAS'!$S$57))) | O13: =IF((M13=""),(NA()),((L13*100)/N13)) -> #N/A
B14: CÁLCULO PESO DE TRABAJO | L14: =IF(AND(J14<>"",K14<>""),J14+K14,"") | N14: =IF((M14=""),(""),((('Perfil F-v DOMINADAS'!$S$56-M14)/-'Perfil F-v DOMINADAS'!$S$57))) | O14: =IF((M14=""),(NA()),((L14*100)/N14)) -> #N/A
B15: % 1RM de trabajo | D15: Peso a utilizar | L15: =IF(AND(J15<>"",K15<>""),J15+K15,"") | N15: =IF((M15=""),(""),((('Perfil F-v DOMINADAS'!$S$56-M15)/-'Perfil F-v DOMINADAS'!$S$57))) | O15: =IF((M15=""),(NA()),((L15*100)/N15)) -> #N/A
B16: 70 | D16: =(D12*B16)/100 -> 86.206897 | L16: =IF(AND(J16<>"",K16<>""),J16+K16,"") | N16: =IF((M16=""),(""),((('Perfil F-v DOMINADAS'!$S$56-M16)/-'Perfil F-v DOMINADAS'!$S$57))) | O16: =IF((M16=""),(NA()),((L16*100)/N16)) -> #N/A
L17: =IF(AND(J17<>"",K17<>""),J17+K17,"") | N17: =IF((M17=""),(""),((('Perfil F-v DOMINADAS'!$S$56-M17)/-'Perfil F-v DOMINADAS'!$S$57))) | O17: =IF((M17=""),(NA()),((L17*100)/N17)) -> #N/A
B18: PESO BARRA | D18: PESO MINIMO DISCO | L18: =IF(AND(J18<>"",K18<>""),J18+K18,"") | N18: =IF((M18=""),(""),((('Perfil F-v DOMINADAS'!$S$56-M18)/-'Perfil F-v DOMINADAS'!$S$57))) | O18: =IF((M18=""),(NA()),((L18*100)/N18)) -> #N/A
B19: 20 | D19: 1.25 | L19: =IF(AND(J19<>"",K19<>""),J19+K19,"") | N19: =IF((M19=""),(""),((('Perfil F-v DOMINADAS'!$S$56-M19)/-'Perfil F-v DOMINADAS'!$S$57))) | O19: =IF((M19=""),(NA()),((L19*100)/N19)) -> #N/A
L20: =IF(AND(J20<>"",K20<>""),J20+K20,"") | N20: =IF((M20=""),(""),((('Perfil F-v DOMINADAS'!$S$56-M20)/-'Perfil F-v DOMINADAS'!$S$57))) | O20: =IF((M20=""),(NA()),((L20*100)/N20)) -> #N/A
L21: =IF(AND(J21<>"",K21<>""),J21+K21,"") | N21: =IF((M21=""),(""),((('Perfil F-v DOMINADAS'!$S$56-M21)/-'Perfil F-v DOMINADAS'!$S$57))) | O21: =IF((M21=""),(NA()),((L21*100)/N21)) -> #N/A
B22: ='Perfil F-v PRESS BANCA'!B21 | D22: ='Perfil F-v PRESS BANCA'!C21 | L22: =IF(AND(J22<>"",K22<>""),J22+K22,"") | N22: =IF((M22=""),(""),((('Perfil F-v DOMINADAS'!$S$56-M22)/-'Perfil F-v DOMINADAS'!$S$57))) | O22: =IF((M22=""),(NA()),((L22*100)/N22)) -> #N/A
L23: =IF(AND(J23<>"",K23<>""),J23+K23,"") | N23: =IF((M23=""),(""),((('Perfil F-v DOMINADAS'!$S$56-M23)/-'Perfil F-v DOMINADAS'!$S$57))) | O23: =IF((M23=""),(NA()),((L23*100)/N23)) -> #N/A
L24: =IF(AND(J24<>"",K24<>""),J24+K24,"") | N24: =IF((M24=""),(""),((('Perfil F-v DOMINADAS'!$S$56-M24)/-'Perfil F-v DOMINADAS'!$S$57))) | O24: =IF((M24=""),(NA()),((L24*100)/N24)) -> #N/A
L25: =IF(AND(J25<>"",K25<>""),J25+K25,"") | N25: =IF((M25=""),(""),((('Perfil F-v DOMINADAS'!$S$56-M25)/-'Perfil F-v DOMINADAS'!$S$57))) | O25: =IF((M25=""),(NA()),((L25*100)/N25)) -> #N/A
L26: =IF(AND(J26<>"",K26<>""),J26+K26,"") | N26: =IF((M26=""),(""),((('Perfil F-v DOMINADAS'!$S$56-M26)/-'Perfil F-v DOMINADAS'!$S$57))) | O26: =IF((M26=""),(NA()),((L26*100)/N26)) -> #N/A
L27: =IF(AND(J27<>"",K27<>""),J27+K27,"") | N27: =IF((M27=""),(""),((('Perfil F-v DOMINADAS'!$S$56-M27)/-'Perfil F-v DOMINADAS'!$S$57))) | O27: =IF((M27=""),(NA()),((L27*100)/N27)) -> #N/A
L28: =IF(AND(J28<>"",K28<>""),J28+K28,"") | N28: =IF((M28=""),(""),((('Perfil F-v DOMINADAS'!$S$56-M28)/-'Perfil F-v DOMINADAS'!$S$57))) | O28: =IF((M28=""),(NA()),((L28*100)/N28)) -> #N/A
L29: =IF(AND(J29<>"",K29<>""),J29+K29,"") | N29: =IF((M29=""),(""),((('Perfil F-v DOMINADAS'!$S$56-M29)/-'Perfil F-v DOMINADAS'!$S$57))) | O29: =IF((M29=""),(NA()),((L29*100)/N29)) -> #N/A
L30: =IF(AND(J30<>"",K30<>""),J30+K30,"") | N30: =IF((M30=""),(""),((('Perfil F-v DOMINADAS'!$S$56-M30)/-'Perfil F-v DOMINADAS'!$S$57))) | O30: =IF((M30=""),(NA()),((L30*100)/N30)) -> #N/A
L31: =IF(AND(J31<>"",K31<>""),J31+K31,"") | N31: =IF((M31=""),(""),((('Perfil F-v DOMINADAS'!$S$56-M31)/-'Perfil F-v DOMINADAS'!$S$57))) | O31: =IF((M31=""),(NA()),((L31*100)/N31)) -> #N/A
L32: =IF(AND(J32<>"",K32<>""),J32+K32,"") | N32: =IF((M32=""),(""),((('Perfil F-v DOMINADAS'!$S$56-M32)/-'Perfil F-v DOMINADAS'!$S$57))) | O32: =IF((M32=""),(NA()),((L32*100)/N32)) -> #N/A
L33: =IF(AND(J33<>"",K33<>""),J33+K33,"") | N33: =IF((M33=""),(""),((('Perfil F-v DOMINADAS'!$S$56-M33)/-'Perfil F-v DOMINADAS'!$S$57))) | O33: =IF((M33=""),(NA()),((L33*100)/N33)) -> #N/A
A37: GRÁFICAS | I37: PERFIL | Q37: DATOS (no editable)
A38: ='Perfil F-v DOMINADAS'!M42 -> PRESS DE BANCA
K40: CELDAS EN COLOR ROJO EDITABLES | R40: ='Perfil F-v DOMINADAS'!M42 -> PRESS DE BANCA
K41: ="PERFIL"&" "& M42 -> PERFIL PRESS DE BANCA | R41: CONSTANTE TEST PERFIL | T41: =FIXED(INTERCEPT('Perfil F-v DOMINADAS'!M46:M50,'Perfil F-v DOMINADAS'!L46:L50),4) -> 0,9600
L42: EJERCICIO | M42: PRESS DE BANCA | R42: PENDIENTE TEST PERFIL | T42: =FIXED(SLOPE('Perfil F-v DOMINADAS'!M46:M50,'Perfil F-v DOMINADAS'!L46:L50),4) -> -0,0060
K43: % 1RM conservador | L43: VELOCIDAD UMBRAL | M43: 0.18 | R43: ECUACIÓN TEST PERFIL | T43: =CONCATENATE("Y=",T42,"x + ",T41) -> Y=-0,0060x + 0,9600
K44: aconsejado para | L44: TEST | R44: Se sustituye Y por V. Umbral: | T44: =CONCATENATE("X=((",T41,"-",'Perfil F-v DOMINADAS'!$M$43,")/",-T42,")") -> X=((0,9600-0,18)/0,006)
K45: realizar el test | L45: Peso (kg) | M45: VELOCIDAD | R45: 1 RM (se despeja la x) | T45: =-(T41-'Perfil F-v DOMINADAS'!M43)/T42 -> 130
K46: 0.75 | L46: 60 | M46: 0.6 | R46: R2 TEST PERFIL | T46: =RSQ('Perfil F-v DOMINADAS'!M46:M50,'Perfil F-v DOMINADAS'!L46:L50) -> 1
...
