Workbook

Sheet Copia de Introducción
A17: Bienvenido/a a RV Strength
B19: ALEX
B20: AGUIRRE
A22: RM
A23: SQUAT | C23: BENCH PRESS | E23: DEADLIFT
A24: 180 | C24: 115 | E24: 240
A26: ="TOTAL: "&SUM(A24:F25)&" kg" -> TOTAL: 535 kg
A27: LISTA DE RM
A28: SQUAT | C28: BENCH PRESS | E28: DEALIFT
A30: Ejercicio | B30: Récord | C30: Ejercicio | D30: Récord | E30: Ejercicio | F30: Récord
F31: 210
D67: Copyright©2023 RV Strength™

Sheet Copia de Calentamiento
D1: CALENTAMIENTO
B13: DÍA / MOVIMIENTO | C13: OBJETIVO | D13: EJERCICIO | E13: SETS / REPS / TIEMPO/INTENSIDAD | F13: VÍDEO | G13: NOTAS DEL ENTRENADOR
C14: Entrada en calor | D14: Foam Roller
B15: SQ | C15: Movilidad | D15: Cat Camel | E15: 1x18¬20 | F15: video
C16: Movilidad | D16: Rotaciones escapulares | E16: 3x12¬14 | F16: video | G16: Hacia adelante, atras y alternas
C17: Movilidad | D17: Rotaciones torácicas | E17: 2x16¬18 | F17: video
C18: Activación | D18: Bird dog | E18: 2x12
C19: Movilidad | D19: Dorsiflexion | E19: 2x20 | F19: video
C20: Activación
B21: BP | C21: Movilidad | D21: Band pull apart | E21: 1x16¬18 | F21: video
C22: Activación | D22: Mangito rotador | E22: 1x12¬14
C23: Activación | D23: Band pull over | E23: 1x12¬14
B25: DL | C25: Movilidad | D25: Glute bridge | E25: 1x20 | F25: video
C26: Movilidad | D26: Dead bug | E26: 1x20
C27: Movilidad | D27: Extension femoral | E27: 2x12¬14 | F27: video

Sheet Copia de Estructura por Bloques
S2: CUANTIFACIÓN DE LAS MÉTRICAS
CA4: BÁSICOS IMPULSO
G5: ESTRUCTURA POR BLOQUES | CB5: S1 | CC5: S2 | CD5: S3 | CE5: S4 | CF5: S5 | CG5: S6 | CH5: S7 | CI5: S8 | CJ5: S9 | CK5: S10 | CL5: S11 | CM5: S12 | CN5: S13 | CO5: S14 | CP5: S15 | CQ5: S16 | CR5: S17 | CS5: S18 | CT5: S19 | CU5: S20 | CV5: S21 | CW5: S22 | CX5: S23 | CY5: S24 | CZ5: S25 | DA5: S26 | DB5: S27 | DC5: S28 | DD5: S29 | DE5: S30 | DF5: S31 | DG5: S32 | DH5: S33 | DI5: S34 | DJ5: S35 | DK5: S36 | DL5: S37 | DM5: S38 | DN5: S39 | DO5: S40 | DP5: S41 | DQ5: S42 | DR5: S43 | DS5: S44 | DT5: S45 | DU5: S46 | DV5: S47 | DW5: S48 | DX5: S49 | DY5: S50 | DZ5: S51 | EA5: S52 | EB5: S53 | EC5: S54
CA6: SQ | CB6: =IFERROR(INDIRECT("'Bloque "&V24&" Semana "&V23&"'"&"!"&"CD15"),"") | CC6: =IFERROR(INDIRECT("'Bloque "&W24&" Semana "&W23&"'"&"!"&"CD15"),"") | CD6: =IFERROR(INDIRECT("'Bloque "&X24&" Semana "&X23&"'"&"!"&"CD15"),"") | CE6: =IFERROR(INDIRECT("'Bloque "&Y24&" Semana "&Y23&"'"&"!"&"CD15"),"") | CF6: =IFERROR(INDIRECT("'Bloque "&Z24&" Semana "&Z23&"'"&"!"&"CD15"),"") | CG6: =IFERROR(INDIRECT("'Bloque "&AA24&" Semana "&AA23&"'"&"!"&"CD15"),"") | CH6: =IFERROR(INDIRECT("'Bloque "&AB24&" Semana "&AB23&"'"&"!"&"CD15"),"") | CI6: =IFERROR(INDIRECT("'Bloque "&AC24&" Semana "&AC23&"'"&"!"&"CD15"),"") | ... DB6: =IFERROR(INDIRECT("'Bloque "&AV24&" Semana "&AV23&"'"&"!"&"CD15"),"") | DC6: =IFERROR(INDIRECT("'Bloque "&V41&" Semana "&V40&"'"&"!"&"CD15"),"") | DD6: =IFERROR(INDIRECT("'Bloque "&W41&" Semana "&W40&"'"&"!"&"CD15"),"") | DE6: =IFERROR(INDIRECT("'Bloque "&X41&" Semana "&X40&"'"&"!"&"CD15"),"") | DF6: =IFERROR(INDIRECT("'Bloque "&Y41&" Semana "&Y40&"'"&"!"&"CD15"),"") | DG6: =IFERROR(INDIRECT("'Bloque "&Z41&" Semana "&Z40&"'"&"!"&"CD15"),"") | DH6: =IFERROR(INDIRECT("'Bloque "&AA41&" Semana "&AA40&"'"&"!"&"CD15"),"") | DI6: =IFERROR(INDIRECT("'Bloque "&AB41&" Semana "&AB40&"'"&"!"&"CD15"),"") | DJ6: =IFERROR(INDIRECT("'Bloque "&AC41&" Semana "&AC40&"'"&"!"&"CD15"),"") | ... EC6: =IFERROR(INDIRECT("'Bloque "&AV41&" Semana "&AV40&"'"&"!"&"CD15"),"")
CA7: BP | CB7: =IFERROR(INDIRECT("'Bloque "&V24&" Semana "&V23&"'"&"!"&"CD16"),"") | CC7: =IFERROR(INDIRECT("'Bloque "&W24&" Semana "&W23&"'"&"!"&"CD16"),"") | CD7: =IFERROR(INDIRECT("'Bloque "&X24&" Semana "&X23&"'"&"!"&"CD16"),"") | CE7: =IFERROR(INDIRECT("'Bloque "&Y24&" Semana "&Y23&"'"&"!"&"CD16"),"") | CF7: =IFERROR(INDIRECT("'Bloque "&Z24&" Semana "&Z23&"'"&"!"&"CD16"),"") | CG7: =IFERROR(INDIRECT("'Bloque "&AA24&" Semana "&AA23&"'"&"!"&"CD16"),"") | CH7: =IFERROR(INDIRECT("'Bloque "&AB24&" Semana "&AB23&"'"&"!"&"CD16"),"") | CI7: =IFERROR(INDIRECT("'Bloque "&AC24&" Semana "&AC23&"'"&"!"&"CD16"),"") | ... DB7: =IFERROR(INDIRECT("'Bloque "&AV24&" Semana "&AV23&"'"&"!"&"CD16"),"") | DC7: =IFERROR(INDIRECT("'Bloque "&V41&" Semana "&V40&"'"&"!"&"CD16"),"") | DD7: =IFERROR(INDIRECT("'Bloque "&W41&" Semana "&W40&"'"&"!"&"CD16"),"") | DE7: =IFERROR(INDIRECT("'Bloque "&X41&" Semana "&X40&"'"&"!"&"CD16"),"") | DF7: =IFERROR(INDIRECT("'Bloque "&Y41&" Semana "&Y40&"'"&"!"&"CD16"),"") | DG7: =IFERROR(INDIRECT("'Bloque "&Z41&" Semana "&Z40&"'"&"!"&"CD16"),"") | DH7: =IFERROR(INDIRECT("'Bloque "&AA41&" Semana "&AA40&"'"&"!"&"CD16"),"") | DI7: =IFERROR(INDIRECT("'Bloque "&AB41&" Semana "&AB40&"'"&"!"&"CD16"),"") | DJ7: =IFERROR(INDIRECT("'Bloque "&AC41&" Semana "&AC40&"'"&"!"&"CD16"),"") | ... EC7: =IFERROR(INDIRECT("'Bloque "&AV41&" Semana "&AV40&"'"&"!"&"CD16"),"")
CA8: DL | CB8: =IFERROR(INDIRECT("'Bloque "&V24&" Semana "&V23&"'"&"!"&"CD17"),"") | CC8: =IFERROR(INDIRECT("'Bloque "&W24&" Semana "&W23&"'"&"!"&"CD17"),"") | CD8: =IFERROR(INDIRECT("'Bloque "&X24&" Semana "&X23&"'"&"!"&"CD17"),"") | CE8: =IFERROR(INDIRECT("'Bloque "&Y24&" Semana "&Y23&"'"&"!"&"CD17"),"") | CF8: =IFERROR(INDIRECT("'Bloque "&Z24&" Semana "&Z23&"'"&"!"&"CD17"),"") | CG8: =IFERROR(INDIRECT("'Bloque "&AA24&" Semana "&AA23&"'"&"!"&"CD17"),"") | CH8: =IFERROR(INDIRECT("'Bloque "&AB24&" Semana "&AB23&"'"&"!"&"CD17"),"") | CI8: =IFERROR(INDIRECT("'Bloque "&AC24&" Semana "&AC23&"'"&"!"&"CD17"),"") | ... DB8: =IFERROR(INDIRECT("'Bloque "&AV24&" Semana "&AV23&"'"&"!"&"CD17"),"") | DC8: =IFERROR(INDIRECT("'Bloque "&V41&" Semana "&V40&"'"&"!"&"CD17"),"") | DD8: =IFERROR(INDIRECT("'Bloque "&W41&" Semana "&W40&"'"&"!"&"CD17"),"") | DE8: =IFERROR(INDIRECT("'Bloque "&X41&" Semana "&X40&"'"&"!"&"CD17"),"") | DF8: =IFERROR(INDIRECT("'Bloque "&Y41&" Semana "&Y40&"'"&"!"&"CD17"),"") | DG8: =IFERROR(INDIRECT("'Bloque "&Z41&" Semana "&Z40&"'"&"!"&"CD17"),"") | DH8: =IFERROR(INDIRECT("'Bloque "&AA41&" Semana "&AA40&"'"&"!"&"CD17"),"") | DI8: =IFERROR(INDIRECT("'Bloque "&AB41&" Semana "&AB40&"'"&"!"&"CD17"),"") | DJ8: =IFERROR(INDIRECT("'Bloque "&AC41&" Semana "&AC40&"'"&"!"&"CD17"),"") | ... EC8: =IFERROR(INDIRECT("'Bloque "&AV41&" Semana "&AV40&"'"&"!"&"CD17"),"")
F9: SQ | G9: BP | H9: DL | I9: TOTAL | J9: MEJORA EN KG | K9: MEJORA EN %
D10: RM Iniciales | F10: ='Introducción'!A24 -> #REF! | G10: ='Introducción'!C24 -> #REF! | H10: ='Introducción'!E24 -> #REF! | I10: =SUM(F10:H10) -> #REF! | J10: =IFERROR(MID(I11,1,3)-MID(I10,1,3),"") | K10: =IFERROR(MID(I11,1,3)-MID(I10,1,3),"")/MID(I10,1,3) -> #REF!
D11: RM Finales de la temporada | I11: =SUM(F11:H11) -> 0 | S11: PERIODIZACIÓN DE LA TEMPORADA | CA11: BÁSICOS NL
D13: TIPO DE BLOQUE | E13: Nº DEL BLOQUE | F13: OBJETIVOS DEL BLOQUE | G13: ANOTACIONES DEL BLOQUE | H13: BLOCK REVIEW | I13: ELECCIÓN DE BÁSICOS | L13: RM's | T13: Fecha de inicio de temporada | U13: 45313 | V13: Semana 1 | W13: Semana 2 | X13: Semana 3 | Y13: Semana 4 | Z13: Semana 5 | AA13: Semana 6 | AB13: Semana 7 | AC13: Semana 8 | AD13: Semana 9 | AE13: Semana 10 | AF13: Semana 11 | AG13: Semana 12 | AH13: Semana 13 | AI13: Semana 14 | AJ13: Semana 15 | AK13: Semana 16 | AL13: Semana 17 | AM13: Semana 18 | AN13: Semana 19 | AO13: Semana 20 | AP13: Semana 21 | AQ13: Semana 22 | AR13: Semana 23 | AS13: Semana 24 | AT13: Semana 25 | AU13: Semana 26 | AV13: Semana 27 | CB13: S1 | CC13: S2 | CD13: S3 | CE13: S4 | CF13: S5 | CG13: S6 | CH13: S7 | CI13: S8 | CJ13: S9 | CK13: S10 | CL13: S11 | CM13: S12 | CN13: S13 | CO13: S14 | CP13: S15 | CQ13: S16 | CR13: S17 | CS13: S18 | CT13: S19 | CU13: S20 | CV13: S21 | CW13: S22 | CX13: S23 | CY13: S24 | CZ13: S25 | DA13: S26 | DB13: S27 | DC13: S28 | DD13: S29 | DE13: S30 | DF13: S31 | DG13: S32 | DH13: S33 | DI13: S34 | DJ13: S35 | DK13: S36 | DL13: S37 | DM13: S38 | DN13: S39 | DO13: S40 | DP13: S41 | DQ13: S42 | DR13: S43 | DS13: S44 | DT13: S45 | DU13: S46 | DV13: S47 | DW13: S48 | DX13: S49 | DY13: S50 | DZ13: S51 | EA13: S52 | EB13: S53 | EC13: S54
I14: SQ | J14: BP | K14: DL | L14: SQ | M14: BP | N14: DL | T14: Leyenda | V14: =TEXT(V15,"mmmm") -> enero | W14: =TEXT(W15,"mmmm") -> enero | X14: =TEXT(X15,"mmmm") -> febrero | Y14: =TEXT(Y15,"mmmm") -> febrero | Z14: =TEXT(Z15,"mmmm") -> febrero | AA14: =TEXT(AA15,"mmmm") -> febrero | AB14: =TEXT(AB15,"mmmm") -> marzo | AC14: =TEXT(AC15,"mmmm") -> marzo | ... AV14: =TEXT(AV15,"mmmm") -> julio | CA14: SQ | CB14: =IFERROR(INDIRECT("'Bloque "&V24&" Semana "&V23&"'"&"!"&"CB15"),"") | CC14: =IFERROR(INDIRECT("'Bloque "&W24&" Semana "&W23&"'"&"!"&"CB15"),"") | CD14: =IFERROR(INDIRECT("'Bloque "&X24&" Semana "&X23&"'"&"!"&"CB15"),"") | CE14: =IFERROR(INDIRECT("'Bloque "&Y24&" Semana "&Y23&"'"&"!"&"CB15"),"") | CF14: =IFERROR(INDIRECT("'Bloque "&Z24&" Semana "&Z23&"'"&"!"&"CB15"),"") | CG14: =IFERROR(INDIRECT("'Bloque "&AA24&" Semana "&AA23&"'"&"!"&"CB15"),"") | CH14: =IFERROR(INDIRECT("'Bloque "&AB24&" Semana "&AB23&"'"&"!"&"CB15"),"") | CI14: =IFERROR(INDIRECT("'Bloque "&AC24&" Semana "&AC23&"'"&"!"&"CB15"),"") | ... DB14: =IFERROR(INDIRECT("'Bloque "&AV24&" Semana "&AV23&"'"&"!"&"CB15"),"") | DC14: =IFERROR(INDIRECT("'Bloque "&V41&" Semana "&V40&"'"&"!"&"CB15"),"") | DD14: =IFERROR(INDIRECT("'Bloque "&W41&" Semana "&W40&"'"&"!"&"CB15"),"") | DE14: =IFERROR(INDIRECT("'Bloque "&X41&" Semana "&X40&"'"&"!"&"CB15"),"") | DF14: =IFERROR(INDIRECT("'Bloque "&Y41&" Semana "&Y40&"'"&"!"&"CB15"),"") | DG14: =IFERROR(INDIRECT("'Bloque "&Z41&" Semana "&Z40&"'"&"!"&"CB15"),"") | DH14: =IFERROR(INDIRECT("'Bloque "&AA41&" Semana "&AA40&"'"&"!"&"CB15"),"") | DI14: =IFERROR(INDIRECT("'Bloque "&AB41&" Semana "&AB40&"'"&"!"&"CB15"),"") | DJ14: =IFERROR(INDIRECT("'Bloque "&AC41&" Semana "&AC40&"'"&"!"&"CB15"),"") | ... EC14: =IFERROR(INDIRECT("'Bloque "&AV41&" Semana "&AV40&"'"&"!"&"CB15"),"")
D15: HIPERTROFIA | E15: 1 | T15: Competición | U15: =TEXT($U$13,"dddd") -> lunes | V15: =U13 -> 45313 | W15: =V15+7 -> 45320 | X15: =W15+7 -> 45327 | Y15: =X15+7 -> 45334 | Z15: =Y15+7 -> 45341 | AA15: =Z15+7 -> 45348 | AB15: =AA15+7 -> 45355 | AC15: =AB15+7 -> 45362 | AD15: =AC15+7 -> 45369 | ... AV15: =AU15+7 -> 45495 | CA15: BP | CB15: =IFERROR(INDIRECT("'Bloque "&V24&" Semana "&V23&"'"&"!"&"CB16"),"") | CC15: =IFERROR(INDIRECT("'Bloque "&W24&" Semana "&W23&"'"&"!"&"CB16"),"") | CD15: =IFERROR(INDIRECT("'Bloque "&X24&" Semana "&X23&"'"&"!"&"CB16"),"") | CE15: =IFERROR(INDIRECT("'Bloque "&Y24&" Semana "&Y23&"'"&"!"&"CB16"),"") | CF15: =IFERROR(INDIRECT("'Bloque "&Z24&" Semana "&Z23&"'"&"!"&"CB16"),"") | CG15: =IFERROR(INDIRECT("'Bloque "&AA24&" Semana "&AA23&"'"&"!"&"CB16"),"") | CH15: =IFERROR(INDIRECT("'Bloque "&AB24&" Semana "&AB23&"'"&"!"&"CB16"),"") | CI15: =IFERROR(INDIRECT("'Bloque "&AC24&" Semana "&AC23&"'"&"!"&"CB16"),"") | ... DB15: =IFERROR(INDIRECT("'Bloque "&AV24&" Semana "&AV23&"'"&"!"&"CB16"),"") | DC15: =IFERROR(INDIRECT("'Bloque "&V41&" Semana "&V40&"'"&"!"&"CB16"),"") | DD15: =IFERROR(INDIRECT("'Bloque "&W41&" Semana "&W40&"'"&"!"&"CB16"),"") | DE15: =IFERROR(INDIRECT("'Bloque "&X41&" Semana "&X40&"'"&"!"&"CB16"),"") | DF15: =IFERROR(INDIRECT("'Bloque "&Y41&" Semana "&Y40&"'"&"!"&"CB16"),"") | DG15: =IFERROR(INDIRECT("'Bloque "&Z41&" Semana "&Z40&"'"&"!"&"CB16"),"") | DH15: =IFERROR(INDIRECT("'Bloque "&AA41&" Semana "&AA40&"'"&"!"&"CB16"),"") | DI15: =IFERROR(INDIRECT("'Bloque "&AB41&" Semana "&AB40&"'"&"!"&"CB16"),"") | DJ15: =IFERROR(INDIRECT("'Bloque "&AC41&" Semana "&AC40&"'"&"!"&"CB16"),"") | ... EC15: =IFERROR(INDIRECT("'Bloque "&AV41&" Semana "&AV40&"'"&"!"&"CB16"),"")
T16: Tapering | U16: =TEXT($U$13+1,"dddd") -> martes | V16: =V15+1 -> 45314 | W16: =W15+1 -> 45321 | X16: =X15+1 -> 45328 | Y16: =Y15+1 -> 45335 | Z16: =Z15+1 -> 45342 | AA16: =AA15+1 -> 45349 | AB16: =AB15+1 -> 45356 | AC16: =AC15+1 -> 45363 | ... AV16: =AV15+1 -> 45496 | CA16: DL | CB16: =IFERROR(INDIRECT("'Bloque "&V24&" Semana "&V23&"'"&"!"&"CB17"),"") | CC16: =IFERROR(INDIRECT("'Bloque "&W24&" Semana "&W23&"'"&"!"&"CB17"),"") | CD16: =IFERROR(INDIRECT("'Bloque "&X24&" Semana "&X23&"'"&"!"&"CB17"),"") | CE16: =IFERROR(INDIRECT("'Bloque "&Y24&" Semana "&Y23&"'"&"!"&"CB17"),"") | CF16: =IFERROR(INDIRECT("'Bloque "&Z24&" Semana "&Z23&"'"&"!"&"CB17"),"") | CG16: =IFERROR(INDIRECT("'Bloque "&AA24&" Semana "&AA23&"'"&"!"&"CB17"),"") | CH16: =IFERROR(INDIRECT("'Bloque "&AB24&" Semana "&AB23&"'"&"!"&"CB17"),"") | CI16: =IFERROR(INDIRECT("'Bloque "&AC24&" Semana "&AC23&"'"&"!"&"CB17"),"") | ... DB16: =IFERROR(INDIRECT("'Bloque "&AV24&" Semana "&AV23&"'"&"!"&"CB17"),"") | DC16: =IFERROR(INDIRECT("'Bloque "&V41&" Semana "&V40&"'"&"!"&"CB17"),"") | DD16: =IFERROR(INDIRECT("'Bloque "&W41&" Semana "&W40&"'"&"!"&"CB17"),"") | DE16: =IFERROR(INDIRECT("'Bloque "&X41&" Semana "&X40&"'"&"!"&"CB17"),"") | DF16: =IFERROR(INDIRECT("'Bloque "&Y41&" Semana "&Y40&"'"&"!"&"CB17"),"") | DG16: =IFERROR(INDIRECT("'Bloque "&Z41&" Semana "&Z40&"'"&"!"&"CB17"),"") | DH16: =IFERROR(INDIRECT("'Bloque "&AA41&" Semana "&AA40&"'"&"!"&"CB17"),"") | DI16: =IFERROR(INDIRECT("'Bloque "&AB41&" Semana "&AB40&"'"&"!"&"CB17"),"") | DJ16: =IFERROR(INDIRECT("'Bloque "&AC41&" Semana "&AC40&"'"&"!"&"CB17"),"") | ... EC16: =IFERROR(INDIRECT("'Bloque "&AV41&" Semana "&AV40&"'"&"!"&"CB17"),"")
T17: Peaking | U17: =TEXT($U$13+2,"dddd") -> miércoles | V17: =V16+1 -> 45315 | W17: =W16+1 -> 45322 | X17: =X16+1 -> 45329 | Y17: =Y16+1 -> 45336 | Z17: =Z16+1 -> 45343 | AA17: =AA16+1 -> 45350 | AB17: =AB16+1 -> 45357 | AC17: =AC16+1 -> 45364 | ... AV17: =AV16+1 -> 45497
T18: Volumen | U18: =TEXT($U$13+3,"dddd") -> jueves | V18: =V17+1 -> 45316 | W18: =W17+1 -> 45323 | X18: =X17+1 -> 45330 | Y18: =Y17+1 -> 45337 | Z18: =Z17+1 -> 45344 | AA18: =AA17+1 -> 45351 | AB18: =AB17+1 -> 45358 | AC18: =AC17+1 -> 45365 | ... AV18: =AV17+1 -> 45498
T19: Fuerza Base | U19: =TEXT($U$13+4,"dddd") -> viernes | V19: =V18+1 -> 45317 | W19: =W18+1 -> 45324 | X19: =X18+1 -> 45331 | Y19: =Y18+1 -> 45338 | Z19: =Z18+1 -> 45345 | AA19: =AA18+1 -> 45352 | AB19: =AB18+1 -> 45359 | AC19: =AC18+1 -> 45366 | ... AV19: =AV18+1 -> 45499
T20: Hipertrofia | U20: =TEXT($U$13+5,"dddd") -> sábado | V20: =V19+1 -> 45318 | W20: =W19+1 -> 45325 | X20: =X19+1 -> 45332 | Y20: =Y19+1 -> 45339 | Z20: =Z19+1 -> 45346 | AA20: =AA19+1 -> 45353 | AB20: =AB19+1 -> 45360 | AC20: =AC19+1 -> 45367 | ... AV20: =AV19+1 -> 45500
T21: Bloque de volumen (Hipertrofia) | U21: =TEXT($U$13+6,"dddd") -> domingo | V21: =V20+1 -> 45319 | W21: =W20+1 -> 45326 | X21: =X20+1 -> 45333 | Y21: =Y20+1 -> 45340 | Z21: =Z20+1 -> 45347 | AA21: =AA20+1 -> 45354 | AB21: =AB20+1 -> 45361 | AC21: =AC20+1 -> 45368 | ... AV21: =AV20+1 -> 45501 | CA21: BÁSICOS pred1RM
T22: Bloque de fuerza (Hipertrofia) | U22: Observaciones | CB22: S1 | CC22: S2 | CD22: S3 | CE22: S4 | CF22: S5 | CG22: S6 | CH22: S7 | CI22: S8 | CJ22: S9 | CK22: S10 | CL22: S11 | CM22: S12 | CN22: S13 | CO22: S14 | CP22: S15 | CQ22: S16 | CR22: S17 | CS22: S18 | CT22: S19 | CU22: S20 | CV22: S21 | CW22: S22 | CX22: S23 | CY22: S24 | CZ22: S25 | DA22: S26 | DB22: S27 | DC22: S28 | DD22: S29 | DE22: S30 | DF22: S31 | DG22: S32 | DH22: S33 | DI22: S34 | DJ22: S35 | DK22: S36 | DL22: S37 | DM22: S38 | DN22: S39 | DO22: S40 | DP22: S41 | DQ22: S42 | DR22: S43 | DS22: S44 | DT22: S45 | DU22: S46 | DV22: S47 | DW22: S48 | DX22: S49 | DY22: S50 | DZ22: S51 | EA22: S52 | EB22: S53 | EC22: S54
T23: Bloque de intensificación (Hipertrofia) | U23: Nº Microciclo | V23: 1 | CA23: SQ | CB23: =IFERROR(INDIRECT("'Bloque "&V24&" Semana "&V23&"'"&"!"&"CE15"),"") | CC23: =IFERROR(INDIRECT("'Bloque "&W24&" Semana "&W23&"'"&"!"&"CE15"),"") | CD23: =IFERROR(INDIRECT("'Bloque "&X24&" Semana "&X23&"'"&"!"&"CE15"),"") | CE23: =IFERROR(INDIRECT("'Bloque "&Y24&" Semana "&Y23&"'"&"!"&"CE15"),"") | CF23: =IFERROR(INDIRECT("'Bloque "&Z24&" Semana "&Z23&"'"&"!"&"CE15"),"") | CG23: =IFERROR(INDIRECT("'Bloque "&AA24&" Semana "&AA23&"'"&"!"&"CE15"),"") | CH23: =IFERROR(INDIRECT("'Bloque "&AB24&" Semana "&AB23&"'"&"!"&"CE15"),"") | CI23: =IFERROR(INDIRECT("'Bloque "&AC24&" Semana "&AC23&"'"&"!"&"CE15"),"") | ... DB23: =IFERROR(INDIRECT("'Bloque "&AV24&" Semana "&AV23&"'"&"!"&"CE15"),"") | DC23: =IFERROR(INDIRECT("'Bloque "&V41&" Semana "&V40&"'"&"!"&"CE15"),"") | DD23: =IFERROR(INDIRECT("'Bloque "&W41&" Semana "&W40&"'"&"!"&"CE15"),"") | DE23: =IFERROR(INDIRECT("'Bloque "&X41&" Semana "&X40&"'"&"!"&"CE15"),"") | DF23: =IFERROR(INDIRECT("'Bloque "&Y41&" Semana "&Y40&"'"&"!"&"CE15"),"") | DG23: =IFERROR(INDIRECT("'Bloque "&Z41&" Semana "&Z40&"'"&"!"&"CE15"),"") | DH23: =IFERROR(INDIRECT("'Bloque "&AA41&" Semana "&AA40&"'"&"!"&"CE15"),"") | DI23: =IFERROR(INDIRECT("'Bloque "&AB41&" Semana "&AB40&"'"&"!"&"CE15"),"") | DJ23: =IFERROR(INDIRECT("'Bloque "&AC41&" Semana "&AC40&"'"&"!"&"CE15"),"") | ... EC23: =IFERROR(INDIRECT("'Bloque "&AV41&" Semana "&AV40&"'"&"!"&"CE15"),"")
T24: Pivot | U24: Nº Bloque | V24: 1 | CA24: BP | CB24: =IFERROR(INDIRECT("'Bloque "&V24&" Semana "&V23&"'"&"!"&"CE16"),"") | CC24: =IFERROR(INDIRECT("'Bloque "&W24&" Semana "&W23&"'"&"!"&"CE16"),"") | CD24: =IFERROR(INDIRECT("'Bloque "&X24&" Semana "&X23&"'"&"!"&"CE16"),"") | CE24: =IFERROR(INDIRECT("'Bloque "&Y24&" Semana "&Y23&"'"&"!"&"CE16"),"") | CF24: =IFERROR(INDIRECT("'Bloque "&Z24&" Semana "&Z23&"'"&"!"&"CE16"),"") | CG24: =IFERROR(INDIRECT("'Bloque "&AA24&" Semana "&AA23&"'"&"!"&"CE16"),"") | CH24: =IFERROR(INDIRECT("'Bloque "&AB24&" Semana "&AB23&"'"&"!"&"CE16"),"") | CI24: =IFERROR(INDIRECT("'Bloque "&AC24&" Semana "&AC23&"'"&"!"&"CE16"),"") | ... DB24: =IFERROR(INDIRECT("'Bloque "&AV24&" Semana "&AV23&"'"&"!"&"CE16"),"") | DC24: =IFERROR(INDIRECT("'Bloque "&V41&" Semana "&V40&"'"&"!"&"CE16"),"") | DD24: =IFERROR(INDIRECT("'Bloque "&W41&" Semana "&W40&"'"&"!"&"CE16"),"") | DE24: =IFERROR(INDIRECT("'Bloque "&X41&" Semana "&X40&"'"&"!"&"CE16"),"") | DF24: =IFERROR(INDIRECT("'Bloque "&Y41&" Semana "&Y40&"'"&"!"&"CE16"),"") | DG24: =IFERROR(INDIRECT("'Bloque "&Z41&" Semana "&Z40&"'"&"!"&"CE16"),"") | DH24: =IFERROR(INDIRECT("'Bloque "&AA41&" Semana "&AA40&"'"&"!"&"CE16"),"") | DI24: =IFERROR(INDIRECT("'Bloque "&AB41&" Semana "&AB40&"'"&"!"&"CE16"),"") | DJ24: =IFERROR(INDIRECT("'Bloque "&AC41&" Semana "&AC40&"'"&"!"&"CE16"),"") | ... EC24: =IFERROR(INDIRECT("'Bloque "&AV41&" Semana "&AV40&"'"&"!"&"CE16"),"")
U25: Tipo de bloque | V25: HIPERTROFIA | CA25: DL | CB25: =IFERROR(INDIRECT("'Bloque "&V24&" Semana "&V23&"'"&"!"&"CE17"),"") | CC25: =IFERROR(INDIRECT("'Bloque "&W24&" Semana "&W23&"'"&"!"&"CE17"),"") | CD25: =IFERROR(INDIRECT("'Bloque "&X24&" Semana "&X23&"'"&"!"&"CE17"),"") | CE25: =IFERROR(INDIRECT("'Bloque "&Y24&" Semana "&Y23&"'"&"!"&"CE17"),"") | CF25: =IFERROR(INDIRECT("'Bloque "&Z24&" Semana "&Z23&"'"&"!"&"CE17"),"") | CG25: =IFERROR(INDIRECT("'Bloque "&AA24&" Semana "&AA23&"'"&"!"&"CE17"),"") | CH25: =IFERROR(INDIRECT("'Bloque "&AB24&" Semana "&AB23&"'"&"!"&"CE17"),"") | CI25: =IFERROR(INDIRECT("'Bloque "&AC24&" Semana "&AC23&"'"&"!"&"CE17"),"") | ... DB25: =IFERROR(INDIRECT("'Bloque "&AV24&" Semana "&AV23&"'"&"!"&"CE17"),"") | DC25: =IFERROR(INDIRECT("'Bloque "&V41&" Semana "&V40&"'"&"!"&"CE17"),"") | DD25: =IFERROR(INDIRECT("'Bloque "&W41&" Semana "&W40&"'"&"!"&"CE17"),"") | DE25: =IFERROR(INDIRECT("'Bloque "&X41&" Semana "&X40&"'"&"!"&"CE17"),"") | DF25: =IFERROR(INDIRECT("'Bloque "&Y41&" Semana "&Y40&"'"&"!"&"CE17"),"") | DG25: =IFERROR(INDIRECT("'Bloque "&Z41&" Semana "&Z40&"'"&"!"&"CE17"),"") | DH25: =IFERROR(INDIRECT("'Bloque "&AA41&" Semana "&AA40&"'"&"!"&"CE17"),"") | DI25: =IFERROR(INDIRECT("'Bloque "&AB41&" Semana "&AB40&"'"&"!"&"CE17"),"") | DJ25: =IFERROR(INDIRECT("'Bloque "&AC41&" Semana "&AC40&"'"&"!"&"CE17"),"") | ... EC25: =IFERROR(INDIRECT("'Bloque "&AV41&" Semana "&AV40&"'"&"!"&"CE17"),"")
U26: Fase | V26: GPP | CA26: TOTAL | CB26: =IFERROR(INDIRECT("'Bloque "&V24&" Semana "&V23&"'"&"!"&"CE18"),"") | CC26: =IFERROR(INDIRECT("'Bloque "&W24&" Semana "&W23&"'"&"!"&"CE18"),"") | CD26: =IFERROR(INDIRECT("'Bloque "&X24&" Semana "&X23&"'"&"!"&"CE18"),"") | CE26: =IFERROR(INDIRECT("'Bloque "&Y24&" Semana "&Y23&"'"&"!"&"CE18"),"") | CF26: =IFERROR(INDIRECT("'Bloque "&Z24&" Semana "&Z23&"'"&"!"&"CE18"),"") | CG26: =IFERROR(INDIRECT("'Bloque "&AA24&" Semana "&AA23&"'"&"!"&"CE18"),"") | CH26: =IFERROR(INDIRECT("'Bloque "&AB24&" Semana "&AB23&"'"&"!"&"CE18"),"") | CI26: =IFERROR(INDIRECT("'Bloque "&AC24&" Semana "&AC23&"'"&"!"&"CE18"),"") | ... DB26: =IFERROR(INDIRECT("'Bloque "&AV24&" Semana "&AV23&"'"&"!"&"CE18"),"") | DC26: =IFERROR(INDIRECT("'Bloque "&V41&" Semana "&V40&"'"&"!"&"CE18"),"") | DD26: =IFERROR(INDIRECT("'Bloque "&W41&" Semana "&W40&"'"&"!"&"CE18"),"") | DE26: =IFERROR(INDIRECT("'Bloque "&X41&" Semana "&X40&"'"&"!"&"CE18"),"") | DF26: =IFERROR(INDIRECT("'Bloque "&Y41&" Semana "&Y40&"'"&"!"&"CE18"),"") | DG26: =IFERROR(INDIRECT("'Bloque "&Z41&" Semana "&Z40&"'"&"!"&"CE18"),"") | DH26: =IFERROR(INDIRECT("'Bloque "&AA41&" Semana "&AA40&"'"&"!"&"CE18"),"") | DI26: =IFERROR(INDIRECT("'Bloque "&AB41&" Semana "&AB40&"'"&"!"&"CE18"),"") | DJ26: =IFERROR(INDIRECT("'Bloque "&AC41&" Semana "&AC40&"'"&"!"&"CE18"),"") | ... EC26: =IFERROR(INDIRECT("'Bloque "&AV41&" Semana "&AV40&"'"&"!"&"CE18"),"")
CA28: FATIGA SEMANAL
CB29: S1 | CC29: S2 | CD29: S3 | CE29: S4 | CF29: S5 | CG29: S6 | CH29: S7 | CI29: S8 | CJ29: S9 | CK29: S10 | CL29: S11 | CM29: S12 | CN29: S13 | CO29: S14 | CP29: S15 | CQ29: S16 | CR29: S17 | CS29: S18 | CT29: S19 | CU29: S20 | CV29: S21 | CW29: S22 | CX29: S23 | CY29: S24 | CZ29: S25 | DA29: S26 | DB29: S27 | DC29: S28 | DD29: S29 | DE29: S30 | DF29: S31 | DG29: S32 | DH29: S33 | DI29: S34 | DJ29: S35 | DK29: S36 | DL29: S37 | DM29: S38 | DN29: S39 | DO29: S40 | DP29: S41 | DQ29: S42 | DR29: S43 | DS29: S44 | DT29: S45 | DU29: S46 | DV29: S47 | DW29: S48 | DX29: S49 | DY29: S50 | DZ29: S51 | EA29: S52 | EB29: S53 | EC29: S54
V30: Semana 28 | W30: Semana 29 | X30: Semana 30 | Y30: Semana 31 | Z30: Semana 32 | AA30: Semana 33 | AB30: Semana 34 | AC30: Semana 35 | AD30: Semana 36 | AE30: Semana 37 | AF30: Semana 38 | AG30: Semana 39 | AH30: Semana 40 | AI30: Semana 41 | AJ30: Semana 42 | AK30: Semana 43 | AL30: Semana 44 | AM30: Semana 45 | AN30: Semana 46 | AO30: Semana 47 | AP30: Semana 48 | AQ30: Semana 49 | AR30: Semana 50 | AS30: Semana 51 | AT30: Semana 52 | AU30: Semana 53 | AV30: Semana 54 | CA30: FATIGA | CB30: =IFERROR(INDIRECT("'Bloque "&V24&" Semana "&V23&"'"&"!"&"AK17"),"") | CC30: =IFERROR(INDIRECT("'Bloque "&W24&" Semana "&W23&"'"&"!"&"AK17"),"") | CD30: =IFERROR(INDIRECT("'Bloque "&X24&" Semana "&X23&"'"&"!"&"AK17"),"") | CE30: =IFERROR(INDIRECT("'Bloque "&Y24&" Semana "&Y23&"'"&"!"&"AK17"),"") | CF30: =IFERROR(INDIRECT("'Bloque "&Z24&" Semana "&Z23&"'"&"!"&"AK17"),"") | CG30: =IFERROR(INDIRECT("'Bloque "&AA24&" Semana "&AA23&"'"&"!"&"AK17"),"") | CH30: =IFERROR(INDIRECT("'Bloque "&AB24&" Semana "&AB23&"'"&"!"&"AK17"),"") | CI30: =IFERROR(INDIRECT("'Bloque "&AC24&" Semana "&AC23&"'"&"!"&"AK17"),"") | ... DB30: =IFERROR(INDIRECT("'Bloque "&AV24&" Semana "&AV23&"'"&"!"&"AK17"),"") | DC30: =IFERROR(INDIRECT("'Bloque "&V41&" Semana "&V40&"'"&"!"&"AK17"),"") | DD30: =IFERROR(INDIRECT("'Bloque "&W41&" Semana "&W40&"'"&"!"&"AK17"),"") | DE30: =IFERROR(INDIRECT("'Bloque "&X41&" Semana "&X40&"'"&"!"&"AK17"),"") | DF30: =IFERROR(INDIRECT("'Bloque "&Y41&" Semana "&Y40&"'"&"!"&"AK17"),"") | DG30: =IFERROR(INDIRECT("'Bloque "&Z41&" Semana "&Z40&"'"&"!"&"AK17"),"") | DH30: =IFERROR(INDIRECT("'Bloque "&AA41&" Semana "&AA40&"'"&"!"&"AK17"),"") | DI30: =IFERROR(INDIRECT("'Bloque "&AB41&" Semana "&AB40&"'"&"!"&"AK17"),"") | DJ30: =IFERROR(INDIRECT("'Bloque "&AC41&" Semana "&AC40&"'"&"!"&"AK17"),"") | ... EC30: =IFERROR(INDIRECT("'Bloque "&AV41&" Semana "&AV40&"'"&"!"&"AK17"),"")
V31: =TEXT(V32,"mmmm") -> julio | W31: =TEXT(W32,"mmmm") -> agosto | X31: =TEXT(X32,"mmmm") -> agosto | Y31: =TEXT(Y32,"mmmm") -> agosto | Z31: =TEXT(Z32,"mmmm") -> agosto | AA31: =TEXT(AA32,"mmmm") -> septiembre | AB31: =TEXT(AB32,"mmmm") -> septiembre | AC31: =TEXT(AC32,"mmmm") -> septiembre | ... AV31: =TEXT(AV32,"mmmm") -> enero | CA31: REC | CB31: =IFERROR(INDIRECT("'Bloque "&V24&" Semana "&V23&"'"&"!"&"BM16"),"") | CC31: =IFERROR(INDIRECT("'Bloque "&W24&" Semana "&W23&"'"&"!"&"BM16"),"") | CD31: =IFERROR(INDIRECT("'Bloque "&X24&" Semana "&X23&"'"&"!"&"BM16"),"") | CE31: =IFERROR(INDIRECT("'Bloque "&Y24&" Semana "&Y23&"'"&"!"&"BM16"),"") | CF31: =IFERROR(INDIRECT("'Bloque "&Z24&" Semana "&Z23&"'"&"!"&"BM16"),"") | CG31: =IFERROR(INDIRECT("'Bloque "&AA24&" Semana "&AA23&"'"&"!"&"BM16"),"") | CH31: =IFERROR(INDIRECT("'Bloque "&AB24&" Semana "&AB23&"'"&"!"&"BM16"),"") | CI31: =IFERROR(INDIRECT("'Bloque "&AC24&" Semana "&AC23&"'"&"!"&"BM16"),"") | ... DB31: =IFERROR(INDIRECT("'Bloque "&AV24&" Semana "&AV23&"'"&"!"&"BM16"),"") | DC31: =IFERROR(INDIRECT("'Bloque "&V41&" Semana "&V40&"'"&"!"&"BM16"),"") | DD31: =IFERROR(INDIRECT("'Bloque "&W41&" Semana "&W40&"'"&"!"&"BM16"),"") | DE31: =IFERROR(INDIRECT("'Bloque "&X41&" Semana "&X40&"'"&"!"&"BM16"),"") | DF31: =IFERROR(INDIRECT("'Bloque "&Y41&" Semana "&Y40&"'"&"!"&"BM16"),"") | DG31: =IFERROR(INDIRECT("'Bloque "&Z41&" Semana "&Z40&"'"&"!"&"BM16"),"") | DH31: =IFERROR(INDIRECT("'Bloque "&AA41&" Semana "&AA40&"'"&"!"&"BM16"),"") | DI31: =IFERROR(INDIRECT("'Bloque "&AB41&" Semana "&AB40&"'"&"!"&"BM16"),"") | DJ31: =IFERROR(INDIRECT("'Bloque "&AC41&" Semana "&AC40&"'"&"!"&"BM16"),"") | ... EC31: =IFERROR(INDIRECT("'Bloque "&AV41&" Semana "&AV40&"'"&"!"&"BM16"),"")
U32: =TEXT($U$13,"dddd") -> lunes | V32: =AV15+7 -> 45502 | W32: =V32+7 -> 45509 | X32: =W32+7 -> 45516 | Y32: =X32+7 -> 45523 | Z32: =Y32+7 -> 45530 | AA32: =Z32+7 -> 45537 | AB32: =AA32+7 -> 45544 | AC32: =AB32+7 -> 45551 | AD32: =AC32+7 -> 45558 | ... AV32: =AU32+7 -> 45684 | CA32: sRPE | CB32: =IFERROR(INDIRECT("'Bloque "&V24&" Semana "&V23&"'"&"!"&"BI16"),"") | CC32: =IFERROR(INDIRECT("'Bloque "&W24&" Semana "&W23&"'"&"!"&"BI16"),"") | CD32: =IFERROR(INDIRECT("'Bloque "&X24&" Semana "&X23&"'"&"!"&"BI16"),"") | CE32: =IFERROR(INDIRECT("'Bloque "&Y24&" Semana "&Y23&"'"&"!"&"BI16"),"") | CF32: =IFERROR(INDIRECT("'Bloque "&Z24&" Semana "&Z23&"'"&"!"&"BI16"),"") | CG32: =IFERROR(INDIRECT("'Bloque "&AA24&" Semana "&AA23&"'"&"!"&"BI16"),"") | CH32: =IFERROR(INDIRECT("'Bloque "&AB24&" Semana "&AB23&"'"&"!"&"BI16"),"") | CI32: =IFERROR(INDIRECT("'Bloque "&AC24&" Semana "&AC23&"'"&"!"&"BI16"),"") | ... DB32: =IFERROR(INDIRECT("'Bloque "&AV24&" Semana "&AV23&"'"&"!"&"BI16"),"") | DC32: =IFERROR(INDIRECT("'Bloque "&V41&" Semana "&V40&"'"&"!"&"BI16"),"") | DD32: =IFERROR(INDIRECT("'Bloque "&W41&" Semana "&W40&"'"&"!"&"BI16"),"") | DE32: =IFERROR(INDIRECT("'Bloque "&X41&" Semana "&X40&"'"&"!"&"BI16"),"") | DF32: =IFERROR(INDIRECT("'Bloque "&Y41&" Semana "&Y40&"'"&"!"&"BI16"),"") | DG32: =IFERROR(INDIRECT("'Bloque "&Z41&" Semana "&Z40&"'"&"!"&"BI16"),"") | DH32: =IFERROR(INDIRECT("'Bloque "&AA41&" Semana "&AA40&"'"&"!"&"BI16"),"") | DI32: =IFERROR(INDIRECT("'Bloque "&AB41&" Semana "&AB40&"'"&"!"&"BI16"),"") | DJ32: =IFERROR(INDIRECT("'Bloque "&AC41&" Semana "&AC40&"'"&"!"&"BI16"),"") | ... EC32: =IFERROR(INDIRECT("'Bloque "&AV41&" Semana "&AV40&"'"&"!"&"BI16"),"")
U33: =TEXT($U$13+1,"dddd") -> martes | V33: =V32+1 -> 45503 | W33: =W32+1 -> 45510 | X33: =X32+1 -> 45517 | Y33: =Y32+1 -> 45524 | Z33: =Z32+1 -> 45531 | AA33: =AA32+1 -> 45538 | AB33: =AB32+1 -> 45545 | AC33: =AC32+1 -> 45552 | ... AV33: =AV32+1 -> 45685
U34: =TEXT($U$13+2,"dddd") -> miércoles | V34: =V33+1 -> 45504 | W34: =W33+1 -> 45511 | X34: =X33+1 -> 45518 | Y34: =Y33+1 -> 45525 | Z34: =Z33+1 -> 45532 | AA34: =AA33+1 -> 45539 | AB34: =AB33+1 -> 45546 | AC34: =AC33+1 -> 45553 | ... AV34: =AV33+1 -> 45686
U35: =TEXT($U$13+3,"dddd") -> jueves | V35: =V34+1 -> 45505 | W35: =W34+1 -> 45512 | X35: =X34+1 -> 45519 | Y35: =Y34+1 -> 45526 | Z35: =Z34+1 -> 45533 | AA35: =AA34+1 -> 45540 | AB35: =AB34+1 -> 45547 | AC35: =AC34+1 -> 45554 | ... AV35: =AV34+1 -> 45687 | CA35: TONELAJE
U36: =TEXT($U$13+4,"dddd") -> viernes | V36: =V35+1 -> 45506 | W36: =W35+1 -> 45513 | X36: =X35+1 -> 45520 | Y36: =Y35+1 -> 45527 | Z36: =Z35+1 -> 45534 | AA36: =AA35+1 -> 45541 | AB36: =AB35+1 -> 45548 | AC36: =AC35+1 -> 45555 | ... AV36: =AV35+1 -> 45688 | CB36: S1 | CC36: S2 | CD36: S3 | CE36: S4 | CF36: S5 | CG36: S6 | CH36: S7 | CI36: S8 | CJ36: S9 | CK36: S10 | CL36: S11 | CM36: S12 | CN36: S13 | CO36: S14 | CP36: S15 | CQ36: S16 | CR36: S17 | CS36: S18 | CT36: S19 | CU36: S20 | CV36: S21 | CW36: S22 | CX36: S23 | CY36: S24 | CZ36: S25 | DA36: S26 | DB36: S27 | DC36: S28 | DD36: S29 | DE36: S30 | DF36: S31 | DG36: S32 | DH36: S33 | DI36: S34 | DJ36: S35 | DK36: S36 | DL36: S37 | DM36: S38 | DN36: S39 | DO36: S40 | DP36: S41 | DQ36: S42 | DR36: S43 | DS36: S44 | DT36: S45 | DU36: S46 | DV36: S47 | DW36: S48 | DX36: S49 | DY36: S50 | DZ36: S51 | EA36: S52 | EB36: S53 | EC36: S54
U37: =TEXT($U$13+5,"dddd") -> sábado | V37: =V36+1 -> 45507 | W37: =W36+1 -> 45514 | X37: =X36+1 -> 45521 | Y37: =Y36+1 -> 45528 | Z37: =Z36+1 -> 45535 | AA37: =AA36+1 -> 45542 | AB37: =AB36+1 -> 45549 | AC37: =AC36+1 -> 45556 | ... AV37: =AV36+1 -> 45689 | CA37: SQ | CB37: =IFERROR(INDIRECT("'Bloque "&V24&" Semana "&V23&"'"&"!"&"CC15"),"") | CC37: =IFERROR(INDIRECT("'Bloque "&W24&" Semana "&W23&"'"&"!"&"CC15"),"") | CD37: =IFERROR(INDIRECT("'Bloque "&X24&" Semana "&X23&"'"&"!"&"CC15"),"") | CE37: =IFERROR(INDIRECT("'Bloque "&Y24&" Semana "&Y23&"'"&"!"&"CC15"),"") | CF37: =IFERROR(INDIRECT("'Bloque "&Z24&" Semana "&Z23&"'"&"!"&"CC15"),"") | CG37: =IFERROR(INDIRECT("'Bloque "&AA24&" Semana "&AA23&"'"&"!"&"CC15"),"") | CH37: =IFERROR(INDIRECT("'Bloque "&AB24&" Semana "&AB23&"'"&"!"&"CC15"),"") | CI37: =IFERROR(INDIRECT("'Bloque "&AC24&" Semana "&AC23&"'"&"!"&"CC15"),"") | ... DB37: =IFERROR(INDIRECT("'Bloque "&AV24&" Semana "&AV23&"'"&"!"&"CC15"),"") | DC37: =IFERROR(INDIRECT("'Bloque "&V41&" Semana "&V40&"'"&"!"&"CC15"),"") | DD37: =IFERROR(INDIRECT("'Bloque "&W41&" Semana "&W40&"'"&"!"&"CC15"),"") | DE37: =IFERROR(INDIRECT("'Bloque "&X41&" Semana "&X40&"'"&"!"&"CC15"),"") | DF37: =IFERROR(INDIRECT("'Bloque "&Y41&" Semana "&Y40&"'"&"!"&"CC15"),"") | DG37: =IFERROR(INDIRECT("'Bloque "&Z41&" Semana "&Z40&"'"&"!"&"CC15"),"") | DH37: =IFERROR(INDIRECT("'Bloque "&AA41&" Semana "&AA40&"'"&"!"&"CC15"),"") | DI37: =IFERROR(INDIRECT("'Bloque "&AB41&" Semana "&AB40&"'"&"!"&"CC15"),"") | DJ37: =IFERROR(INDIRECT("'Bloque "&AC41&" Semana "&AC40&"'"&"!"&"CC15"),"") | ... EC37: =IFERROR(INDIRECT("'Bloque "&AV41&" Semana "&AV40&"'"&"!"&"CC15"),"")
U38: =TEXT($U$13+6,"dddd") -> domingo | V38: =V37+1 -> 45508 | W38: =W37+1 -> 45515 | X38: =X37+1 -> 45522 | Y38: =Y37+1 -> 45529 | Z38: =Z37+1 -> 45536 | AA38: =AA37+1 -> 45543 | AB38: =AB37+1 -> 45550 | AC38: =AC37+1 -> 45557 | ... AV38: =AV37+1 -> 45690 | CA38: BP | CB38: =IFERROR(INDIRECT("'Bloque "&V24&" Semana "&V23&"'"&"!"&"CC16"),"") | CC38: =IFERROR(INDIRECT("'Bloque "&W24&" Semana "&W23&"'"&"!"&"CC16"),"") | CD38: =IFERROR(INDIRECT("'Bloque "&X24&" Semana "&X23&"'"&"!"&"CC16"),"") | CE38: =IFERROR(INDIRECT("'Bloque "&Y24&" Semana "&Y23&"'"&"!"&"CC16"),"") | CF38: =IFERROR(INDIRECT("'Bloque "&Z24&" Semana "&Z23&"'"&"!"&"CC16"),"") | CG38: =IFERROR(INDIRECT("'Bloque "&AA24&" Semana "&AA23&"'"&"!"&"CC16"),"") | CH38: =IFERROR(INDIRECT("'Bloque "&AB24&" Semana "&AB23&"'"&"!"&"CC16"),"") | CI38: =IFERROR(INDIRECT("'Bloque "&AC24&" Semana "&AC23&"'"&"!"&"CC16"),"") | ... DB38: =IFERROR(INDIRECT("'Bloque "&AV24&" Semana "&AV23&"'"&"!"&"CC16"),"") | DC38: =IFERROR(INDIRECT("'Bloque "&V41&" Semana "&V40&"'"&"!"&"CC16"),"") | DD38: =IFERROR(INDIRECT("'Bloque "&W41&" Semana "&W40&"'"&"!"&"CC16"),"") | DE38: =IFERROR(INDIRECT("'Bloque "&X41&" Semana "&X40&"'"&"!"&"CC16"),"") | DF38: =IFERROR(INDIRECT("'Bloque "&Y41&" Semana "&Y40&"'"&"!"&"CC16"),"") | DG38: =IFERROR(INDIRECT("'Bloque "&Z41&" Semana "&Z40&"'"&"!"&"CC16"),"") | DH38: =IFERROR(INDIRECT("'Bloque "&AA41&" Semana "&AA40&"'"&"!"&"CC16"),"") | DI38: =IFERROR(INDIRECT("'Bloque "&AB41&" Semana "&AB40&"'"&"!"&"CC16"),"") | DJ38: =IFERROR(INDIRECT("'Bloque "&AC41&" Semana "&AC40&"'"&"!"&"CC16"),"") | ... EC38: =IFERROR(INDIRECT("'Bloque "&AV41&" Semana "&AV40&"'"&"!"&"CC16"),"")
U39: Observaciones | CA39: DL | CB39: =IFERROR(INDIRECT("'Bloque "&V24&" Semana "&V23&"'"&"!"&"CC17"),"") | CC39: =IFERROR(INDIRECT("'Bloque "&W24&" Semana "&W23&"'"&"!"&"CC17"),"") | CD39: =IFERROR(INDIRECT("'Bloque "&X24&" Semana "&X23&"'"&"!"&"CC17"),"") | CE39: =IFERROR(INDIRECT("'Bloque "&Y24&" Semana "&Y23&"'"&"!"&"CC17"),"") | CF39: =IFERROR(INDIRECT("'Bloque "&Z24&" Semana "&Z23&"'"&"!"&"CC17"),"") | CG39: =IFERROR(INDIRECT("'Bloque "&AA24&" Semana "&AA23&"'"&"!"&"CC17"),"") | CH39: =IFERROR(INDIRECT("'Bloque "&AB24&" Semana "&AB23&"'"&"!"&"CC17"),"") | CI39: =IFERROR(INDIRECT("'Bloque "&AC24&" Semana "&AC23&"'"&"!"&"CC17"),"") | ... DB39: =IFERROR(INDIRECT("'Bloque "&AV24&" Semana "&AV23&"'"&"!"&"CC17"),"") | DC39: =IFERROR(INDIRECT("'Bloque "&V41&" Semana "&V40&"'"&"!"&"CC17"),"") | DD39: =IFERROR(INDIRECT("'Bloque "&W41&" Semana "&W40&"'"&"!"&"CC17"),"") | DE39: =IFERROR(INDIRECT("'Bloque "&X41&" Semana "&X40&"'"&"!"&"CC17"),"") | DF39: =IFERROR(INDIRECT("'Bloque "&Y41&" Semana "&Y40&"'"&"!"&"CC17"),"") | DG39: =IFERROR(INDIRECT("'Bloque "&Z41&" Semana "&Z40&"'"&"!"&"CC17"),"") | DH39: =IFERROR(INDIRECT("'Bloque "&AA41&" Semana "&AA40&"'"&"!"&"CC17"),"") | DI39: =IFERROR(INDIRECT("'Bloque "&AB41&" Semana "&AB40&"'"&"!"&"CC17"),"") | DJ39: =IFERROR(INDIRECT("'Bloque "&AC41&" Semana "&AC40&"'"&"!"&"CC17"),"") | ... EC39: =IFERROR(INDIRECT("'Bloque "&AV41&" Semana "&AV40&"'"&"!"&"CC17"),"")
U40: Nº Microciclo
U41: Nº Bloque | CA41: TONELAJE VS I.M.R.
U42: Tipo de bloque | CA42: SQ | CB42: S1 | CC42: S2 | CD42: S3 | CE42: S4 | CF42: S5 | CG42: S6 | CH42: S7 | CI42: S8 | CJ42: S9 | CK42: S10 | CL42: S11 | CM42: S12 | CN42: S13 | CO42: S14 | CP42: S15 | CQ42: S16 | CR42: S17 | CS42: S18 | CT42: S19 | CU42: S20 | CV42: S21 | CW42: S22 | CX42: S23 | CY42: S24 | CZ42: S25 | DA42: S26 | DB42: S27 | DC42: S28 | DD42: S29 | DE42: S30 | DF42: S31 | DG42: S32 | DH42: S33 | DI42: S34 | DJ42: S35 | DK42: S36 | DL42: S37 | DM42: S38 | DN42: S39 | DO42: S40 | DP42: S41 | DQ42: S42 | DR42: S43 | DS42: S44 | DT42: S45 | DU42: S46 | DV42: S47 | DW42: S48 | DX42: S49 | DY42: S50 | DZ42: S51 | EA42: S52 | EB42: S53 | EC42: S54
U43: Fase | CA43: TONN | CB43: =IFERROR(INDIRECT("'Bloque "&V24&" Semana "&V23&"'"&"!"&"CC15"),"") | CC43: =IFERROR(INDIRECT("'Bloque "&W24&" Semana "&W23&"'"&"!"&"CC15"),"") | CD43: =IFERROR(INDIRECT("'Bloque "&X24&" Semana "&X23&"'"&"!"&"CC15"),"") | CE43: =IFERROR(INDIRECT("'Bloque "&Y24&" Semana "&Y23&"'"&"!"&"CC15"),"") | CF43: =IFERROR(INDIRECT("'Bloque "&Z24&" Semana "&Z23&"'"&"!"&"CC15"),"") | CG43: =IFERROR(INDIRECT("'Bloque "&AA24&" Semana "&AA23&"'"&"!"&"CC15"),"") | CH43: =IFERROR(INDIRECT("'Bloque "&AB24&" Semana "&AB23&"'"&"!"&"CC15"),"") | CI43: =IFERROR(INDIRECT("'Bloque "&AC24&" Semana "&AC23&"'"&"!"&"CC15"),"") | ... DB43: =IFERROR(INDIRECT("'Bloque "&AV24&" Semana "&AV23&"'"&"!"&"CC15"),"") | DC43: =IFERROR(INDIRECT("'Bloque "&V41&" Semana "&V40&"'"&"!"&"CC15"),"") | DD43: =IFERROR(INDIRECT("'Bloque "&W41&" Semana "&W40&"'"&"!"&"CC15"),"") | DE43: =IFERROR(INDIRECT("'Bloque "&X41&" Semana "&X40&"'"&"!"&"CC15"),"") | DF43: =IFERROR(INDIRECT("'Bloque "&Y41&" Semana "&Y40&"'"&"!"&"CC15"),"") | DG43: =IFERROR(INDIRECT("'Bloque "&Z41&" Semana "&Z40&"'"&"!"&"CC15"),"") | DH43: =IFERROR(INDIRECT("'Bloque "&AA41&" Semana "&AA40&"'"&"!"&"CC15"),"") | DI43: =IFERROR(INDIRECT("'Bloque "&AB41&" Semana "&AB40&"'"&"!"&"CC15"),"") | DJ43: =IFERROR(INDIRECT("'Bloque "&AC41&" Semana "&AC40&"'"&"!"&"CC15"),"") | ... EC43: =IFERROR(INDIRECT("'Bloque "&AV41&" Semana "&AV40&"'"&"!"&"CC15"),"")
CA44: I.M.R | CB44: =IFERROR(INDIRECT("'Bloque "&V24&" Semana "&V23&"'"&"!"&"CD15"),"") | CC44: =IFERROR(INDIRECT("'Bloque "&W24&" Semana "&W23&"'"&"!"&"CD15"),"") | CD44: =IFERROR(INDIRECT("'Bloque "&X24&" Semana "&X23&"'"&"!"&"CD15"),"") | CE44: =IFERROR(INDIRECT("'Bloque "&Y24&" Semana "&Y23&"'"&"!"&"CD15"),"") | CF44: =IFERROR(INDIRECT("'Bloque "&Z24&" Semana "&Z23&"'"&"!"&"CD15"),"") | CG44: =IFERROR(INDIRECT("'Bloque "&AA24&" Semana "&AA23&"'"&"!"&"CD15"),"") | CH44: =IFERROR(INDIRECT("'Bloque "&AB24&" Semana "&AB23&"'"&"!"&"CD15"),"") | CI44: =IFERROR(INDIRECT("'Bloque "&AC24&" Semana "&AC23&"'"&"!"&"CD15"),"") | ... DB44: =IFERROR(INDIRECT("'Bloque "&AV24&" Semana "&AV23&"'"&"!"&"CD15"),"") | DC44: =IFERROR(INDIRECT("'Bloque "&V41&" Semana "&V40&"'"&"!"&"CD15"),"") | DD44: =IFERROR(INDIRECT("'Bloque "&W41&" Semana "&W40&"'"&"!"&"CD15"),"") | DE44: =IFERROR(INDIRECT("'Bloque "&X41&" Semana "&X40&"'"&"!"&"CD15"),"") | DF44: =IFERROR(INDIRECT("'Bloque "&Y41&" Semana "&Y40&"'"&"!"&"CD15"),"") | DG44: =IFERROR(INDIRECT("'Bloque "&Z41&" Semana "&Z40&"'"&"!"&"CD15"),"") | DH44: =IFERROR(INDIRECT("'Bloque "&AA41&" Semana "&AA40&"'"&"!"&"CD15"),"") | DI44: =IFERROR(INDIRECT("'Bloque "&AB41&" Semana "&AB40&"'"&"!"&"CD15"),"") | DJ44: =IFERROR(INDIRECT("'Bloque "&AC41&" Semana "&AC40&"'"&"!"&"CD15"),"") | ... EC44: =IFERROR(INDIRECT("'Bloque "&AV41&" Semana "&AV40&"'"&"!"&"CD15"),"")
...

Sheet Copia de Bloque 5 Semana 2
X1: CUANTIFICACIÓN A PARTIR DE LO PRESCRITO | AG1: ="SEGUIMIENTO DE BIENESTAR DE "&'Introducción'!B19&" "&'Introducción'!B20 -> #REF! | BZ1: CUANTIFIFACIÓN A PARTIR DE LO REALIZADO POR EL ATLETA | DK1: S1 | DL1: S2 | DM1: S3 | DN1: S4 | DO1: S5 | DP1: S6 | DQ1: S7 | DR1: S8 | DS1: S9 | DT1: S10 | DU1: S11 | DV1: S12 | DW1: S13 | DX1: S14 | DY1: S15 | DZ1: S16 | EA1: S17 | EB1: S18 | FZ1: SQ | GC1: BP | GF1: DL
J2: DETALLES DEL BLOQUE DE ENTRENAMIENTO | AG2: Instrucciones | DJ2: BÁSICOS TONELAJE | EX2: PR'S RPE CHART | EZ2: MEJOR A 1 | FL2: PR'S RPE CHART | FN2: MEJOR A REPE | FZ2: TONN VS IMR | GC2: TONN VS IMR | GF2: TONN VS IMR
J3: METE MATERIAL | AG3: - Rellena el apartado de "Cuestionario de Bienestar Diario" justo DESPUÉS del calentamiento, ANTES de la sesión principal. - El apartado de "Duración de la sesión" y "RPE de la Sesión" rellenalos unos 15-20 minutos después de haber terminado la sesión. | DK3: {=IF(NOT($D$37=1),IFERROR(INDIRECT("'Bloque "&$D$38&" Semana "&"1"&"'"&"!"&"E37"),""),"S1")} | DL3: {=IF(NOT($D$37=2),IFERROR(INDIRECT("'Bloque "&$D$38&" Semana "&"2"&"'"&"!"&"E37"),""),"S2")} -> S2 | DM3: {=IF(NOT($D$37=3),IFERROR(INDIRECT("'Bloque "&$D$38&" Semana "&"3"&"'"&"!"&"E37"),""),"S3")} | DN3: {=IF(NOT($D$37=4),IFERROR(INDIRECT("'Bloque "&$D$38&" Semana "&"4"&"'"&"!"&"E37"),""),"S4")} | DO3: {=IF(NOT($D$37=5),IFERROR(INDIRECT("'Bloque "&$D$38&" Semana "&"5"&"'"&"!"&"E37"),""),"S5")} | DP3: {=IF(NOT($D$37=6),IFERROR(INDIRECT("'Bloque "&$D$38&" Semana "&"6"&"'"&"!"&"E37"),""),"S6")} | DQ3: {=IF(NOT($D$37=7),IFERROR(INDIRECT("'Bloque "&$D$38&" Semana "&"7"&"'"&"!"&"E37"),""),"S7")} | DR3: {=IF(NOT($D$37=8),IFERROR(INDIRECT("'Bloque "&$D$38&" Semana "&"8"&"'"&"!"&"E37"),""),"S8")} | DS3: {=IF(NOT($D$37=9),IFERROR(INDIRECT("'Bloque "&$D$38&" Semana "&"9"&"'"&"!"&"E37"),""),"S9")} | DT3: {=IF(NOT($D$37=10),IFERROR(INDIRECT("'Bloque "&$D$38&" Semana "&"10"&"'"&"!"&"E37"),""),"S10")} | DU3: {=IF(NOT($D$37=11),IFERROR(INDIRECT("'Bloque "&$D$38&" Semana "&"11"&"'"&"!"&"E37"),""),"S11")} | DV3: {=IF(NOT($D$37=12),IFERROR(INDIRECT("'Bloque "&$D$38&" Semana "&"12"&"'"&"!"&"E37"),""),"S12")} | DW3: {=IF(NOT($D$37=13),IFERROR(INDIRECT("'Bloque "&$D$38&" Semana "&"13"&"'"&"!"&"E37"),""),"S13")} | DX3: {=IF(NOT($D$37=14),IFERROR(INDIRECT("'Bloque "&$D$38&" Semana "&"14"&"'"&"!"&"E37"),""),"S14")} | DY3: {=IF(NOT($D$37=15),IFERROR(INDIRECT("'Bloque "&$D$38&" Semana "&"15"&"'"&"!"&"E37"),""),"S15")} | DZ3: {=IF(NOT($D$37=16),IFERROR(INDIRECT("'Bloque "&$D$38&" Semana "&"16"&"'"&"!"&"E37"),""),"S16")} | EA3: {=IF(NOT($D$37=17),IFERROR(INDIRECT("'Bloque "&$D$38&" Semana "&"17"&"'"&"!"&"E37"),""),"S17")} | EB3: {=IF(NOT($D$37=18),IFERROR(INDIRECT("'Bloque "&$D$38&" Semana "&"18"&"'"&"!"&"E37"),""),"S18")} | ED3: ACCESORIOS SERIES | EX3: @@ | EY3: 1 | EZ3: 2 | FA3: 3 | FB3: 4 | FC3: 5 | FD3: 6 | FE3: 7 | FF3: 8 | FG3: 9 | FH3: 10 | FI3: 11 | FJ3: 12 | FL3: @@ | FM3: 1 | FN3: 2 | FO3: 3 | FP3: 4 | FQ3: 5 | FR3: 6 | FS3: 7 | FT3: 8 | FU3: 9 | FV3: 10 | FW3: 11 | FX3: 12 | GA3: IMR | GB3: TON | GD3: IMR | GE3: TON | GG3: IMR | GH3: TON
DJ4: SQ | DK4: =IFERROR(INDIRECT("'Bloque "&$D$38&" Semana "&MID(DK3,2,2)&"'"&"!"&"CC15"),"") | DL4: =IFERROR(INDIRECT("'Bloque "&$D$38&" Semana "&MID(DL3,2,2)&"'"&"!"&"CC15"),"") | DM4: =IFERROR(INDIRECT("'Bloque "&$D$38&" Semana "&MID(DM3,2,2)&"'"&"!"&"CC15"),"") | DN4: =IFERROR(INDIRECT("'Bloque "&$D$38&" Semana "&MID(DN3,2,2)&"'"&"!"&"CC15"),"") | DO4: =IFERROR(INDIRECT("'Bloque "&$D$38&" Semana "&MID(DO3,2,2)&"'"&"!"&"CC15"),"") | DP4: =IFERROR(INDIRECT("'Bloque "&$D$38&" Semana "&MID(DP3,2,2)&"'"&"!"&"CC15"),"") | DQ4: =IFERROR(INDIRECT("'Bloque "&$D$38&" Semana "&MID(DQ3,2,2)&"'"&"!"&"CC15"),"") | DR4: =IFERROR(INDIRECT("'Bloque "&$D$38&" Semana "&MID(DR3,2,2)&"'"&"!"&"CC15"),"") | ... EB4: =IFERROR(INDIRECT("'Bloque "&$D$38&" Semana "&MID(EB3,2,2)&"'"&"!"&"CC15"),"") | EE4: {=IF(NOT($D$37=1),IFERROR(INDIRECT("'Bloque "&$D$38&" Semana "&"1"&"'"&"!"&"E37"),""),"S1")} | EF4: {=IF(NOT($D$37=2),IFERROR(INDIRECT("'Bloque "&$D$38&" Semana "&"2"&"'"&"!"&"E37"),""),"S2")} -> S2 | EG4: {=IF(NOT($D$37=3),IFERROR(INDIRECT("'Bloque "&$D$38&" Semana "&"3"&"'"&"!"&"E37"),""),"S3")} | EH4: {=IF(NOT($D$37=4),IFERROR(INDIRECT("'Bloque "&$D$38&" Semana "&"4"&"'"&"!"&"E37"),""),"S4")} | EI4: {=IF(NOT($D$37=5),IFERROR(INDIRECT("'Bloque "&$D$38&" Semana "&"5"&"'"&"!"&"E37"),""),"S5")} | EJ4: {=IF(NOT($D$37=6),IFERROR(INDIRECT("'Bloque "&$D$38&" Semana "&"6"&"'"&"!"&"E37"),""),"S6")} | EK4: {=IF(NOT($D$37=7),IFERROR(INDIRECT("'Bloque "&$D$38&" Semana "&"7"&"'"&"!"&"E37"),""),"S7")} | EL4: {=IF(NOT($D$37=8),IFERROR(INDIRECT("'Bloque "&$D$38&" Semana "&"8"&"'"&"!"&"E37"),""),"S8")} | EM4: {=IF(NOT($D$37=9),IFERROR(INDIRECT("'Bloque "&$D$38&" Semana "&"9"&"'"&"!"&"E37"),""),"S9")} | EN4: {=IF(NOT($D$37=10),IFERROR(INDIRECT("'Bloque "&$D$38&" Semana "&"10"&"'"&"!"&"E37"),""),"S10")} | EO4: {=IF(NOT($D$37=11),IFERROR(INDIRECT("'Bloque "&$D$38&" Semana "&"11"&"'"&"!"&"E37"),""),"S11")} | EP4: {=IF(NOT($D$37=12),IFERROR(INDIRECT("'Bloque "&$D$38&" Semana "&"12"&"'"&"!"&"E37"),""),"S12")} | EQ4: {=IF(NOT($D$37=13),IFERROR(INDIRECT("'Bloque "&$D$38&" Semana "&"13"&"'"&"!"&"E37"),""),"S13")} | ER4: {=IF(NOT($D$37=14),IFERROR(INDIRECT("'Bloque "&$D$38&" Semana "&"14"&"'"&"!"&"E37"),""),"S14")} | ES4: {=IF(NOT($D$37=15),IFERROR(INDIRECT("'Bloque "&$D$38&" Semana "&"15"&"'"&"!"&"E37"),""),"S15")} | ET4: {=IF(NOT($D$37=16),IFERROR(INDIRECT("'Bloque "&$D$38&" Semana "&"16"&"'"&"!"&"E37"),""),"S16")} | EU4: {=IF(NOT($D$37=17),IFERROR(INDIRECT("'Bloque "&$D$38&" Semana "&"17"&"'"&"!"&"E37"),""),"S17")} | EV4: {=IF(NOT($D$37=18),IFERROR(INDIRECT("'Bloque "&$D$38&" Semana "&"18"&"'"&"!"&"E37"),""),"S18")} | EX4: 10 | EY4: 1 | EZ4: 0.955 | FA4: 0.922 | FB4: 0.892 | FC4: 0.863 | FD4: 0.837 | FE4: 0.811 | FF4: 0.786 | FG4: 0.762 | FH4: 0.739 | FI4: 0.707 | FJ4: 0.68 | FL4: 10 | FM4: 1 | FN4: 0.965 | FO4: 0.942 | FP4: 0.919 | FQ4: 0.897 | FR4: 0.875 | FS4: 0.854 | FT4: 0.834 | FU4: 0.814 | FV4: 0.794 | FW4: 0.775 | FX4: 0.756 | FZ4: {=IF(NOT($D$37=1),IFERROR(INDIRECT("'Bloque "&$D$38&" Semana "&"1"&"'"&"!"&"E37"),""),"S1")} | GA4: =IFERROR(INDIRECT("'Bloque "&$D$38&" Semana "&MID(FZ4,2,2)&"'"&"!"&"CD15"),"") | GB4: =IFERROR(INDIRECT("'Bloque "&$D$38&" Semana "&MID(FZ4,2,2)&"'"&"!"&"CC15"),"") | GC4: {=IF(NOT($D$37=1),IFERROR(INDIRECT("'Bloque "&$D$38&" Semana "&"1"&"'"&"!"&"E37"),""),"S1")} | GD4: =IFERROR(INDIRECT("'Bloque "&$D$38&" Semana "&MID(GC4,2,2)&"'"&"!"&"CD16"),"") | GE4: =IFERROR(INDIRECT("'Bloque "&$D$38&" Semana "&MID(GC4,2,2)&"'"&"!"&"CC16"),"") | GF4: {=IF(NOT($D$37=1),IFERROR(INDIRECT("'Bloque "&$D$38&" Semana "&"1"&"'"&"!"&"E37"),""),"S1")} | GG4: =IFERROR(INDIRECT("'Bloque "&$D$38&" Semana "&MID(GF4,2,2)&"'"&"!"&"CD17"),"") | GH4: =IFERROR(INDIRECT("'Bloque "&$D$38&" Semana "&MID(GF4,2,2)&"'"&"!"&"CC17"),"")
AG5: - Este cuestionario nos permite ver CÓMO afecta tu día a día al entrenamiento (que días estás más cansado/a, si estás bajando rendimiento por falta de sueño, estrés, etc.) - Las casillas se puntúan del 1 al 7, 1 significa horrible y 7 perfecto. | DJ5: BP | DK5: =IFERROR(INDIRECT("'Bloque "&$D$38&" Semana "&MID(DK3,2,2)&"'"&"!"&"CC16"),"") | DL5: =IFERROR(INDIRECT("'Bloque "&$D$38&" Semana "&MID(DL3,2,2)&"'"&"!"&"CC16"),"") | DM5: =IFERROR(INDIRECT("'Bloque "&$D$38&" Semana "&MID(DM3,2,2)&"'"&"!"&"CC16"),"") | DN5: =IFERROR(INDIRECT("'Bloque "&$D$38&" Semana "&MID(DN3,2,2)&"'"&"!"&"CC16"),"") | DO5: =IFERROR(INDIRECT("'Bloque "&$D$38&" Semana "&MID(DO3,2,2)&"'"&"!"&"CC16"),"") | DP5: =IFERROR(INDIRECT("'Bloque "&$D$38&" Semana "&MID(DP3,2,2)&"'"&"!"&"CC16"),"") | DQ5: =IFERROR(INDIRECT("'Bloque "&$D$38&" Semana "&MID(DQ3,2,2)&"'"&"!"&"CC16"),"") | DR5: =IFERROR(INDIRECT("'Bloque "&$D$38&" Semana "&MID(DR3,2,2)&"'"&"!"&"CC16"),"") | ... EB5: =IFERROR(INDIRECT("'Bloque "&$D$38&" Semana "&MID(EB3,2,2)&"'"&"!"&"CC16"),"") | ED5: =BZ21 -> Dominante de Rodilla | EE5: =IFERROR(INDIRECT("'Bloque "&$D$38&" Semana "&MID(EE4,2,2)&"'"&"!"&"CC21"),"") | EF5: =IFERROR(INDIRECT("'Bloque "&$D$38&" Semana "&MID(EF4,2,2)&"'"&"!"&"CC21"),"") | EG5: =IFERROR(INDIRECT("'Bloque "&$D$38&" Semana "&MID(EG4,2,2)&"'"&"!"&"CC21"),"") | EH5: =IFERROR(INDIRECT("'Bloque "&$D$38&" Semana "&MID(EH4,2,2)&"'"&"!"&"CC21"),"") | EI5: =IFERROR(INDIRECT("'Bloque "&$D$38&" Semana "&MID(EI4,2,2)&"'"&"!"&"CC21"),"") | EJ5: =IFERROR(INDIRECT("'Bloque "&$D$38&" Semana "&MID(EJ4,2,2)&"'"&"!"&"CC21"),"") | EK5: =IFERROR(INDIRECT("'Bloque "&$D$38&" Semana "&MID(EK4,2,2)&"'"&"!"&"CC21"),"") | EL5: =IFERROR(INDIRECT("'Bloque "&$D$38&" Semana "&MID(EL4,2,2)&"'"&"!"&"CC21"),"") | ... EV5: =IFERROR(INDIRECT("'Bloque "&$D$38&" Semana "&MID(EV4,2,2)&"'"&"!"&"CC21"),"") | EX5: 9.5 | EY5: 0.978 | EZ5: 0.939 | FA5: 0.907 | FB5: 0.878 | FC5: 0.85 | FD5: 0.824 | FE5: 0.799 | FF5: 0.774 | FG5: 0.751 | FH5: 0.723 | FI5: 0.694 | FJ5: 0.667 | FL5: 9.5 | FM5: 0.989 | FN5: 0.955 | FO5: 0.932 | FP5: 0.909 | FQ5: 0.887 | FR5: 0.866 | FS5: 0.845 | FT5: 0.825 | FU5: 0.805 | FV5: 0.756 | FW5: 0.767 | FX5: 0.748 | FZ5: {=IF(NOT($D$37=2),IFERROR(INDIRECT("'Bloque "&$D$38&" Semana "&"2"&"'"&"!"&"E37"),""),"S2")} -> S2 | GA5: =IFERROR(INDIRECT("'Bloque "&$D$38&" Semana "&MID(FZ5,2,2)&"'"&"!"&"CD15"),"") | GB5: =IFERROR(INDIRECT("'Bloque "&$D$38&" Semana "&MID(FZ5,2,2)&"'"&"!"&"CC15"),"") | GC5: {=IF(NOT($D$37=2),IFERROR(INDIRECT("'Bloque "&$D$38&" Semana "&"2"&"'"&"!"&"E37"),""),"S2")} -> S2 | GD5: =IFERROR(INDIRECT("'Bloque "&$D$38&" Semana "&MID(GC5,2,2)&"'"&"!"&"CD16"),"") | GE5: =IFERROR(INDIRECT("'Bloque "&$D$38&" Semana "&MID(GC5,2,2)&"'"&"!"&"CC16"),"") | GF5: {=IF(NOT($D$37=2),IFERROR(INDIRECT("'Bloque "&$D$38&" Semana "&"2"&"'"&"!"&"E37"),""),"S2")} -> S2 | GG5: =IFERROR(INDIRECT("'Bloque "&$D$38&" Semana "&MID(GF5,2,2)&"'"&"!"&"CD17"),"") | GH5: =IFERROR(INDIRECT("'Bloque "&$D$38&" Semana "&MID(GF5,2,2)&"'"&"!"&"CC17"),"")
AG6: CUESTIONARIO DE BIENESTAR DIARIO | BR6: DURACIÓN DE LA SESIÓN | BZ6: A PARTIR DE LO REALIZADO POR EL ATLETA | CH6: TASA DE PROGRESIÓN | CO6: 1RM PROYECTADA | DJ6: DL | DK6: =IFERROR(INDIRECT("'Bloque "&$D$38&" Semana "&MID(DK3,2,2)&"'"&"!"&"CC17"),"") | DL6: =IFERROR(INDIRECT("'Bloque "&$D$38&" Semana "&MID(DL3,2,2)&"'"&"!"&"CC17"),"") | DM6: =IFERROR(INDIRECT("'Bloque "&$D$38&" Semana "&MID(DM3,2,2)&"'"&"!"&"CC17"),"") | DN6: =IFERROR(INDIRECT("'Bloque "&$D$38&" Semana "&MID(DN3,2,2)&"'"&"!"&"CC17"),"") | DO6: =IFERROR(INDIRECT("'Bloque "&$D$38&" Semana "&MID(DO3,2,2)&"'"&"!"&"CC17"),"") | DP6: =IFERROR(INDIRECT("'Bloque "&$D$38&" Semana "&MID(DP3,2,2)&"'"&"!"&"CC17"),"") | DQ6: =IFERROR(INDIRECT("'Bloque "&$D$38&" Semana "&MID(DQ3,2,2)&"'"&"!"&"CC17"),"") | DR6: =IFERROR(INDIRECT("'Bloque "&$D$38&" Semana "&MID(DR3,2,2)&"'"&"!"&"CC17"),"") | ... EB6: =IFERROR(INDIRECT("'Bloque "&$D$38&" Semana "&MID(EB3,2,2)&"'"&"!"&"CC17"),"") | ED6: =BZ22 -> Bisagra de Cadera | EE6: =IFERROR(INDIRECT("'Bloque "&$D$38&" Semana "&MID(EE4,2,2)&"'"&"!"&"CC22"),"") | EF6: =IFERROR(INDIRECT("'Bloque "&$D$38&" Semana "&MID(EF4,2,2)&"'"&"!"&"CC22"),"") | EG6: =IFERROR(INDIRECT("'Bloque "&$D$38&" Semana "&MID(EG4,2,2)&"'"&"!"&"CC22"),"") | EH6: =IFERROR(INDIRECT("'Bloque "&$D$38&" Semana "&MID(EH4,2,2)&"'"&"!"&"CC22"),"") | EI6: =IFERROR(INDIRECT("'Bloque "&$D$38&" Semana "&MID(EI4,2,2)&"'"&"!"&"CC22"),"") | EJ6: =IFERROR(INDIRECT("'Bloque "&$D$38&" Semana "&MID(EJ4,2,2)&"'"&"!"&"CC22"),"") | EK6: =IFERROR(INDIRECT("'Bloque "&$D$38&" Semana "&MID(EK4,2,2)&"'"&"!"&"CC22"),"") | EL6: =IFERROR(INDIRECT("'Bloque "&$D$38&" Semana "&MID(EL4,2,2)&"'"&"!"&"CC22"),"") | ... EV6: =IFERROR(INDIRECT("'Bloque "&$D$38&" Semana "&MID(EV4,2,2)&"'"&"!"&"CC22"),"") | EX6: 9 | EY6: 0.955 | EZ6: 0.922 | FA6: 0.892 | FB6: 0.863 | FC6: 0.837 | FD6: 0.811 | FE6: 0.786 | FF6: 0.762 | FG6: 0.739 | FH6: 0.707 | FI6: 0.68 | FJ6: 0.653 | FL6: 9 | FM6: 0.979 | FN6: 0.944 | FO6: 0.922 | FP6: 0.9 | FQ6: 0.878 | FR6: 0.857 | FS6: 0.836 | FT6: 0.816 | FU6: 0.796 | FV6: 0.777 | FW6: 0.758 | FX6: 0.74 | FZ6: {=IF(NOT($D$37=3),IFERROR(INDIRECT("'Bloque "&$D$38&" Semana "&"3"&"'"&"!"&"E37"),""),"S3")} | GA6: =IFERROR(INDIRECT("'Bloque "&$D$38&" Semana "&MID(FZ6,2,2)&"'"&"!"&"CD15"),"") | GB6: =IFERROR(INDIRECT("'Bloque "&$D$38&" Semana "&MID(FZ6,2,2)&"'"&"!"&"CC15"),"") | GC6: {=IF(NOT($D$37=3),IFERROR(INDIRECT("'Bloque "&$D$38&" Semana "&"3"&"'"&"!"&"E37"),""),"S3")} | GD6: =IFERROR(INDIRECT("'Bloque "&$D$38&" Semana "&MID(GC6,2,2)&"'"&"!"&"CD16"),"") | GE6: =IFERROR(INDIRECT("'Bloque "&$D$38&" Semana "&MID(GC6,2,2)&"'"&"!"&"CC16"),"") | GF6: {=IF(NOT($D$37=3),IFERROR(INDIRECT("'Bloque "&$D$38&" Semana "&"3"&"'"&"!"&"E37"),""),"S3")} | GG6: =IFERROR(INDIRECT("'Bloque "&$D$38&" Semana "&MID(GF6,2,2)&"'"&"!"&"CD17"),"") | GH6: =IFERROR(INDIRECT("'Bloque "&$D$38&" Semana "&MID(GF6,2,2)&"'"&"!"&"CC17"),"")
BZ7: POR VARIANTE | CH7: SQ1 Top Set | CI7: <-- ELIGE EL BÁSICO | ED7: =BZ23 -> Empuje Horizontal | EE7: =IFERROR(INDIRECT("'Bloque "&$D$38&" Semana "&MID(EE4,2,2)&"'"&"!"&"CC23"),"") | EF7: =IFERROR(INDIRECT("'Bloque "&$D$38&" Semana "&MID(EF4,2,2)&"'"&"!"&"CC23"),"") | EG7: =IFERROR(INDIRECT("'Bloque "&$D$38&" Semana "&MID(EG4,2,2)&"'"&"!"&"CC23"),"") | EH7: =IFERROR(INDIRECT("'Bloque "&$D$38&" Semana "&MID(EH4,2,2)&"'"&"!"&"CC23"),"") | EI7: =IFERROR(INDIRECT("'Bloque "&$D$38&" Semana "&MID(EI4,2,2)&"'"&"!"&"CC23"),"") | EJ7: =IFERROR(INDIRECT("'Bloque "&$D$38&" Semana "&MID(EJ4,2,2)&"'"&"!"&"CC23"),"") | EK7: =IFERROR(INDIRECT("'Bloque "&$D$38&" Semana "&MID(EK4,2,2)&"'"&"!"&"CC23"),"") | EL7: =IFERROR(INDIRECT("'Bloque "&$D$38&" Semana "&MID(EL4,2,2)&"'"&"!"&"CC23"),"") | ... EV7: =IFERROR(INDIRECT("'Bloque "&$D$38&" Semana "&MID(EV4,2,2)&"'"&"!"&"CC23"),"") | EX7: 8.5 | EY7: 0.939 | EZ7: 0.907 | FA7: 0.878 | FB7: 0.85 | FC7: 0.824 | FD7: 0.799 | FE7: 0.774 | FF7: 0.751 | FG7: 0.723 | FH7: 0.694 | FI7: 0.667 | FJ7: 0.64 | FL7: 8.5 | FM7: 0.968 | FN7: 0.934 | FO7: 0.912 | FP7: 0.89 | FQ7: 0.868 | FR7: 0.848 | FS7: 0.827 | FT7: 0.807 | FU7: 0.788 | FV7: 0.769 | FW7: 0.75 | FX7: 0.732 | FZ7: {=IF(NOT($D$37=4),IFERROR(INDIRECT("'Bloque "&$D$38&" Semana "&"4"&"'"&"!"&"E37"),""),"S4")} | GA7: =IFERROR(INDIRECT("'Bloque "&$D$38&" Semana "&MID(FZ7,2,2)&"'"&"!"&"CD15"),"") | GB7: =IFERROR(INDIRECT("'Bloque "&$D$38&" Semana "&MID(FZ7,2,2)&"'"&"!"&"CC15"),"") | GC7: {=IF(NOT($D$37=4),IFERROR(INDIRECT("'Bloque "&$D$38&" Semana "&"4"&"'"&"!"&"E37"),""),"S4")} | GD7: =IFERROR(INDIRECT("'Bloque "&$D$38&" Semana "&MID(GC7,2,2)&"'"&"!"&"CD16"),"") | GE7: =IFERROR(INDIRECT("'Bloque "&$D$38&" Semana "&MID(GC7,2,2)&"'"&"!"&"CC16"),"") | GF7: {=IF(NOT($D$37=4),IFERROR(INDIRECT("'Bloque "&$D$38&" Semana "&"4"&"'"&"!"&"E37"),""),"S4")} | GG7: =IFERROR(INDIRECT("'Bloque "&$D$38&" Semana "&MID(GF7,2,2)&"'"&"!"&"CD17"),"") | GH7: =IFERROR(INDIRECT("'Bloque "&$D$38&" Semana "&MID(GF7,2,2)&"'"&"!"&"CC17"),"")
AG8: DÍAS DE LA SEMANA | AK8: CALIDAD DEL SUEÑO | AO8: NIVEL DE ESTRÉS | AS8: NIVEL DE FATIGA | AW8: DAÑO MUSCULAR GENERAL (AGUJETAS) | BA8: ESTADO ANÍMICO | BE8: FATIGA DIARIA | BI8: RECUPERACIÓN PERCIBIDA | BM8: RPE DE LA SESIÓN | BR8: HORA DE COMIENZO DEL ENTRENAMIENTO | BU8: HORA DE FINALIZACIÓN DEL ENTRENAMIENTO | BW8: TIEMPO ENTRENADO | BZ8: CALC | CA8: Series | CB8: NL | CC8: TON | CD8: I.M.R. | CE8: e1RM Steve Denovi F1 | CF8: RPE MEDIO | CH8: SEMANAS | CI8: ESQUEMA INICIAL | CJ8: REPS | CK8: CARGA | CL8: AUMENTO DE CARGA (KG) | CM8: RPE | CN8: AUMENTO DE RPE | CO8: CARGA | CP8: PROYECTADA | CQ8: 1RM PROYECTADA MEJOR A REPS | CR8: % MEJORA | CS8: KG | CT8: % | DJ8: BÁSICOS I.M.R. | ED8: =BZ24 -> Empuje Vertical | EE8: =IFERROR(INDIRECT("'Bloque "&$D$38&" Semana "&MID(EE4,2,2)&"'"&"!"&"CC24"),"") | EF8: =IFERROR(INDIRECT("'Bloque "&$D$38&" Semana "&MID(EF4,2,2)&"'"&"!"&"CC24"),"") | EG8: =IFERROR(INDIRECT("'Bloque "&$D$38&" Semana "&MID(EG4,2,2)&"'"&"!"&"CC24"),"") | EH8: =IFERROR(INDIRECT("'Bloque "&$D$38&" Semana "&MID(EH4,2,2)&"'"&"!"&"CC24"),"") | EI8: =IFERROR(INDIRECT("'Bloque "&$D$38&" Semana "&MID(EI4,2,2)&"'"&"!"&"CC24"),"") | EJ8: =IFERROR(INDIRECT("'Bloque "&$D$38&" Semana "&MID(EJ4,2,2)&"'"&"!"&"CC24"),"") | EK8: =IFERROR(INDIRECT("'Bloque "&$D$38&" Semana "&MID(EK4,2,2)&"'"&"!"&"CC24"),"") | EL8: =IFERROR(INDIRECT("'Bloque "&$D$38&" Semana "&MID(EL4,2,2)&"'"&"!"&"CC24"),"") | ... EV8: =IFERROR(INDIRECT("'Bloque "&$D$38&" Semana "&MID(EV4,2,2)&"'"&"!"&"CC24"),"") | EX8: 8 | EY8: 0.922 | EZ8: 0.892 | FA8: 0.863 | FB8: 0.837 | FC8: 0.811 | FD8: 0.786 | FE8: 0.762 | FF8: 0.739 | FG8: 0.707 | FH8: 0.68 | FI8: 0.653 | FJ8: 0.626 | FL8: 8 | FM8: 0.958 | FN8: 0.924 | FO8: 0.902 | FP8: 0.88 | FQ8: 0.859 | FR8: 0.838 | FS8: 0.818 | FT8: 0.799 | FU8: 0.779 | FV8: 0.761 | FW8: 0.742 | FX8: 0.724 | FZ8: {=IF(NOT($D$37=5),IFERROR(INDIRECT("'Bloque "&$D$38&" Semana "&"5"&"'"&"!"&"E37"),""),"S5")} | GA8: =IFERROR(INDIRECT("'Bloque "&$D$38&" Semana "&MID(FZ8,2,2)&"'"&"!"&"CD15"),"") | GB8: =IFERROR(INDIRECT("'Bloque "&$D$38&" Semana "&MID(FZ8,2,2)&"'"&"!"&"CC15"),"") | GC8: {=IF(NOT($D$37=5),IFERROR(INDIRECT("'Bloque "&$D$38&" Semana "&"5"&"'"&"!"&"E37"),""),"S5")} | GD8: =IFERROR(INDIRECT("'Bloque "&$D$38&" Semana "&MID(GC8,2,2)&"'"&"!"&"CD16"),"") | GE8: =IFERROR(INDIRECT("'Bloque "&$D$38&" Semana "&MID(GC8,2,2)&"'"&"!"&"CC16"),"") | GF8: {=IF(NOT($D$37=5),IFERROR(INDIRECT("'Bloque "&$D$38&" Semana "&"5"&"'"&"!"&"E37"),""),"S5")} | GG8: =IFERROR(INDIRECT("'Bloque "&$D$38&" Semana "&MID(GF8,2,2)&"'"&"!"&"CD17"),"") | GH8: =IFERROR(INDIRECT("'Bloque "&$D$38&" Semana "&MID(GF8,2,2)&"'"&"!"&"CC17"),"")
